2018-04-24 13:00:27,540 [django.request:118] [exception:handle_uncaught_exception] [ERROR]- Internal Server Error: /api/add_module/
Traceback (most recent call last):
  File "D:\HttpRunnerManager\HttpRunnerManager\activator.py", line 29, in process
    result = fun(request, index)
TypeError: add_module() takes 1 positional argument but 2 were given

During handling of the above exception, another exception occurred:

Traceback (most recent call last):
  File "E:\Python35\lib\site-packages\django\core\handlers\exception.py", line 35, in inner
    response = get_response(request)
  File "E:\Python35\lib\site-packages\django\core\handlers\base.py", line 128, in _get_response
    response = self.process_exception_by_middleware(e, request)
  File "E:\Python35\lib\site-packages\django\core\handlers\base.py", line 126, in _get_response
    response = wrapped_callback(request, *callback_args, **callback_kwargs)
  File "D:\HttpRunnerManager\HttpRunnerManager\activator.py", line 31, in process
    result = fun(request)
  File "D:\HttpRunnerManager\ApiManager\views.py", line 115, in add_module
    msg = module_info_logic(**module_info)
  File "D:\HttpRunnerManager\ApiManager\utils\common.py", line 135, in module_info_logic
    return add_module_data(type, **kwargs)
  File "D:\HttpRunnerManager\ApiManager\utils\operation.py", line 71, in add_module_data
    belong_project = ProjectInfo.objects.get_pro_name(belong_project, type=False)
  File "D:\HttpRunnerManager\ApiManager\managers.py", line 56, in get_pro_name
    return self.get(project_name__exact=pro_name)
  File "E:\Python35\lib\site-packages\django\db\models\manager.py", line 82, in manager_method
    return getattr(self.get_queryset(), name)(*args, **kwargs)
  File "E:\Python35\lib\site-packages\django\db\models\query.py", line 403, in get
    self.model._meta.object_name
ApiManager.models.DoesNotExist: ProjectInfo matching query does not exist.
2018-04-24 13:05:46,136 [django.request:118] [exception:handle_uncaught_exception] [ERROR]- Internal Server Error: /api/add_module/
Traceback (most recent call last):
  File "E:\Python35\lib\site-packages\django\core\handlers\exception.py", line 35, in inner
    response = get_response(request)
  File "E:\Python35\lib\site-packages\django\core\handlers\base.py", line 128, in _get_response
    response = self.process_exception_by_middleware(e, request)
  File "E:\Python35\lib\site-packages\django\core\handlers\base.py", line 126, in _get_response
    response = wrapped_callback(request, *callback_args, **callback_kwargs)
  File "D:\HttpRunnerManager\HttpRunnerManager\activator.py", line 23, in process
    app = __import__("%s.views" % app)
  File "D:\HttpRunnerManager\ApiManager\views.py", line 10, in <module>
    from ApiManager.utils.common import module_info_logic, project_info_logic, case_info_logic, config_info_logic, \
  File "D:\HttpRunnerManager\ApiManager\utils\common.py", line 6, in <module>
    from ApiManager.utils.operation import add_project_data, add_module_data, add_case_data, add_config_data, \
  File "D:\HttpRunnerManager\ApiManager\utils\operation.py", line 75
    kwargs['belong_project'] = belong_project
         ^
IndentationError: expected an indented block
2018-04-24 13:06:24,848 [HttpRunnerManager:75] [operation:add_module_data] [INFO]- 11模块添加成功
2018-04-24 13:13:47,297 [django.request:118] [exception:handle_uncaught_exception] [ERROR]- Internal Server Error: /api/add_config/
Traceback (most recent call last):
  File "D:\HttpRunnerManager\HttpRunnerManager\activator.py", line 29, in process
    result = fun(request, index)
TypeError: add_config() takes 1 positional argument but 2 were given

During handling of the above exception, another exception occurred:

Traceback (most recent call last):
  File "E:\Python35\lib\site-packages\django\db\models\sql\query.py", line 1683, in add_fields
    join_info = self.setup_joins(name.split(LOOKUP_SEP), opts, alias, allow_many=allow_m2m)
  File "E:\Python35\lib\site-packages\django\db\models\sql\query.py", line 1448, in setup_joins
    names, opts, allow_many, fail_on_missing=True)
  File "E:\Python35\lib\site-packages\django\db\models\sql\query.py", line 1379, in names_to_path
    "Choices are: %s" % (name, ", ".join(available)))
django.core.exceptions.FieldError: Cannot resolve keyword 'pro_name' into field. Choices are: create_time, dev_user, id, moduleinfo, other_desc, project_name, publish_app, responsible_name, simple_desc, test_user, update_time

During handling of the above exception, another exception occurred:

Traceback (most recent call last):
  File "E:\Python35\lib\site-packages\django\core\handlers\exception.py", line 35, in inner
    response = get_response(request)
  File "E:\Python35\lib\site-packages\django\core\handlers\base.py", line 128, in _get_response
    response = self.process_exception_by_middleware(e, request)
  File "E:\Python35\lib\site-packages\django\core\handlers\base.py", line 126, in _get_response
    response = wrapped_callback(request, *callback_args, **callback_kwargs)
  File "D:\HttpRunnerManager\HttpRunnerManager\activator.py", line 31, in process
    result = fun(request)
  File "D:\HttpRunnerManager\ApiManager\views.py", line 162, in add_config
    'project': ProjectInfo.objects.all().values('pro_name').order_by('-create_time')
  File "E:\Python35\lib\site-packages\django\db\models\query.py", line 742, in values
    clone = self._values(*fields, **expressions)
  File "E:\Python35\lib\site-packages\django\db\models\query.py", line 737, in _values
    clone.query.set_values(fields)
  File "E:\Python35\lib\site-packages\django\db\models\sql\query.py", line 1935, in set_values
    self.add_fields(field_names, True)
  File "E:\Python35\lib\site-packages\django\db\models\sql\query.py", line 1706, in add_fields
    "Choices are: %s" % (name, ", ".join(names)))
django.core.exceptions.FieldError: Cannot resolve keyword 'pro_name' into field. Choices are: create_time, dev_user, id, moduleinfo, other_desc, project_name, publish_app, responsible_name, simple_desc, test_user, update_time
2018-04-24 13:13:50,749 [django.request:118] [exception:handle_uncaught_exception] [ERROR]- Internal Server Error: /api/add_case/
Traceback (most recent call last):
  File "D:\HttpRunnerManager\HttpRunnerManager\activator.py", line 29, in process
    result = fun(request, index)
TypeError: add_case() takes 1 positional argument but 2 were given

During handling of the above exception, another exception occurred:

Traceback (most recent call last):
  File "E:\Python35\lib\site-packages\django\db\models\sql\query.py", line 1683, in add_fields
    join_info = self.setup_joins(name.split(LOOKUP_SEP), opts, alias, allow_many=allow_m2m)
  File "E:\Python35\lib\site-packages\django\db\models\sql\query.py", line 1448, in setup_joins
    names, opts, allow_many, fail_on_missing=True)
  File "E:\Python35\lib\site-packages\django\db\models\sql\query.py", line 1379, in names_to_path
    "Choices are: %s" % (name, ", ".join(available)))
django.core.exceptions.FieldError: Cannot resolve keyword 'pro_name' into field. Choices are: create_time, dev_user, id, moduleinfo, other_desc, project_name, publish_app, responsible_name, simple_desc, test_user, update_time

During handling of the above exception, another exception occurred:

Traceback (most recent call last):
  File "E:\Python35\lib\site-packages\django\core\handlers\exception.py", line 35, in inner
    response = get_response(request)
  File "E:\Python35\lib\site-packages\django\core\handlers\base.py", line 128, in _get_response
    response = self.process_exception_by_middleware(e, request)
  File "E:\Python35\lib\site-packages\django\core\handlers\base.py", line 126, in _get_response
    response = wrapped_callback(request, *callback_args, **callback_kwargs)
  File "D:\HttpRunnerManager\HttpRunnerManager\activator.py", line 31, in process
    result = fun(request)
  File "D:\HttpRunnerManager\ApiManager\views.py", line 142, in add_case
    'project': ProjectInfo.objects.all().values('pro_name').order_by('-create_time')
  File "E:\Python35\lib\site-packages\django\db\models\query.py", line 742, in values
    clone = self._values(*fields, **expressions)
  File "E:\Python35\lib\site-packages\django\db\models\query.py", line 737, in _values
    clone.query.set_values(fields)
  File "E:\Python35\lib\site-packages\django\db\models\sql\query.py", line 1935, in set_values
    self.add_fields(field_names, True)
  File "E:\Python35\lib\site-packages\django\db\models\sql\query.py", line 1706, in add_fields
    "Choices are: %s" % (name, ", ".join(names)))
django.core.exceptions.FieldError: Cannot resolve keyword 'pro_name' into field. Choices are: create_time, dev_user, id, moduleinfo, other_desc, project_name, publish_app, responsible_name, simple_desc, test_user, update_time
2018-04-24 13:14:12,718 [django.request:118] [exception:handle_uncaught_exception] [ERROR]- Internal Server Error: /api/add_case/
Traceback (most recent call last):
  File "D:\HttpRunnerManager\HttpRunnerManager\activator.py", line 29, in process
    result = fun(request, index)
TypeError: add_case() takes 1 positional argument but 2 were given

During handling of the above exception, another exception occurred:

Traceback (most recent call last):
  File "E:\Python35\lib\site-packages\django\db\models\sql\query.py", line 1683, in add_fields
    join_info = self.setup_joins(name.split(LOOKUP_SEP), opts, alias, allow_many=allow_m2m)
  File "E:\Python35\lib\site-packages\django\db\models\sql\query.py", line 1448, in setup_joins
    names, opts, allow_many, fail_on_missing=True)
  File "E:\Python35\lib\site-packages\django\db\models\sql\query.py", line 1379, in names_to_path
    "Choices are: %s" % (name, ", ".join(available)))
django.core.exceptions.FieldError: Cannot resolve keyword 'pro_name' into field. Choices are: create_time, dev_user, id, moduleinfo, other_desc, project_name, publish_app, responsible_name, simple_desc, test_user, update_time

During handling of the above exception, another exception occurred:

Traceback (most recent call last):
  File "E:\Python35\lib\site-packages\django\core\handlers\exception.py", line 35, in inner
    response = get_response(request)
  File "E:\Python35\lib\site-packages\django\core\handlers\base.py", line 128, in _get_response
    response = self.process_exception_by_middleware(e, request)
  File "E:\Python35\lib\site-packages\django\core\handlers\base.py", line 126, in _get_response
    response = wrapped_callback(request, *callback_args, **callback_kwargs)
  File "D:\HttpRunnerManager\HttpRunnerManager\activator.py", line 31, in process
    result = fun(request)
  File "D:\HttpRunnerManager\ApiManager\views.py", line 142, in add_case
    'project': ProjectInfo.objects.all().values('pro_name').order_by('-create_time')
  File "E:\Python35\lib\site-packages\django\db\models\query.py", line 742, in values
    clone = self._values(*fields, **expressions)
  File "E:\Python35\lib\site-packages\django\db\models\query.py", line 737, in _values
    clone.query.set_values(fields)
  File "E:\Python35\lib\site-packages\django\db\models\sql\query.py", line 1935, in set_values
    self.add_fields(field_names, True)
  File "E:\Python35\lib\site-packages\django\db\models\sql\query.py", line 1706, in add_fields
    "Choices are: %s" % (name, ", ".join(names)))
django.core.exceptions.FieldError: Cannot resolve keyword 'pro_name' into field. Choices are: create_time, dev_user, id, moduleinfo, other_desc, project_name, publish_app, responsible_name, simple_desc, test_user, update_time
2018-04-24 15:26:30,372 [HttpRunnerManager:58] [views:log_out] [INFO]- yinquanwang退出
2018-04-24 15:26:32,081 [HttpRunnerManager:29] [views:login] [INFO]- yinquanwang 登录成功
2018-04-24 15:51:06,362 [django.request:118] [exception:handle_uncaught_exception] [ERROR]- Internal Server Error: /api/add_module/
Traceback (most recent call last):
  File "D:\HttpRunnerManager\HttpRunnerManager\activator.py", line 29, in process
    result = fun(request, index)
TypeError: add_module() takes 1 positional argument but 2 were given

During handling of the above exception, another exception occurred:

Traceback (most recent call last):
  File "E:\Python35\lib\site-packages\django\core\handlers\exception.py", line 35, in inner
    response = get_response(request)
  File "E:\Python35\lib\site-packages\django\core\handlers\base.py", line 128, in _get_response
    response = self.process_exception_by_middleware(e, request)
  File "E:\Python35\lib\site-packages\django\core\handlers\base.py", line 126, in _get_response
    response = wrapped_callback(request, *callback_args, **callback_kwargs)
  File "D:\HttpRunnerManager\HttpRunnerManager\activator.py", line 31, in process
    result = fun(request)
  File "D:\HttpRunnerManager\ApiManager\views.py", line 115, in add_module
    msg = module_info_logic(**module_info)
  File "D:\HttpRunnerManager\ApiManager\utils\common.py", line 135, in module_info_logic
    return add_module_data(type, **kwargs)
  File "D:\HttpRunnerManager\ApiManager\utils\operation.py", line 73, in add_module_data
    belong_project = ProjectInfo.objects.get_pro_name(belong_project, type=False)
AttributeError: 'ProjectInfoManager' object has no attribute 'get_pro_name'
2018-04-24 15:53:07,108 [django.request:118] [exception:handle_uncaught_exception] [ERROR]- Internal Server Error: /api/add_module/
Traceback (most recent call last):
  File "D:\HttpRunnerManager\HttpRunnerManager\activator.py", line 29, in process
    result = fun(request, index)
TypeError: add_module() takes 1 positional argument but 2 were given

During handling of the above exception, another exception occurred:

Traceback (most recent call last):
  File "D:\HttpRunnerManager\ApiManager\utils\operation.py", line 73, in add_module_data
    belong_project = ProjectInfo.objects.get_pro_name(belong_project, type=False)
  File "D:\HttpRunnerManager\ApiManager\managers.py", line 56, in get_pro_name
    return self.get(project_name__exact=pro_name)
  File "E:\Python35\lib\site-packages\django\db\models\manager.py", line 82, in manager_method
    return getattr(self.get_queryset(), name)(*args, **kwargs)
  File "E:\Python35\lib\site-packages\django\db\models\query.py", line 403, in get
    self.model._meta.object_name
ApiManager.models.DoesNotExist: ProjectInfo matching query does not exist.

During handling of the above exception, another exception occurred:

Traceback (most recent call last):
  File "E:\Python35\lib\site-packages\django\core\handlers\exception.py", line 35, in inner
    response = get_response(request)
  File "E:\Python35\lib\site-packages\django\core\handlers\base.py", line 128, in _get_response
    response = self.process_exception_by_middleware(e, request)
  File "E:\Python35\lib\site-packages\django\core\handlers\base.py", line 126, in _get_response
    response = wrapped_callback(request, *callback_args, **callback_kwargs)
  File "D:\HttpRunnerManager\HttpRunnerManager\activator.py", line 31, in process
    result = fun(request)
  File "D:\HttpRunnerManager\ApiManager\views.py", line 115, in add_module
    msg = module_info_logic(**module_info)
  File "D:\HttpRunnerManager\ApiManager\utils\common.py", line 135, in module_info_logic
    return add_module_data(type, **kwargs)
  File "D:\HttpRunnerManager\ApiManager\utils\operation.py", line 75, in add_module_data
    logging.error('{项目信息读取失败：{belong_project}'.format(belong_project=belong_project))
ValueError: unexpected '{' in field name
2018-04-24 15:53:09,707 [django.request:118] [exception:handle_uncaught_exception] [ERROR]- Internal Server Error: /api/add_module/
Traceback (most recent call last):
  File "D:\HttpRunnerManager\HttpRunnerManager\activator.py", line 29, in process
    result = fun(request, index)
TypeError: add_module() takes 1 positional argument but 2 were given

During handling of the above exception, another exception occurred:

Traceback (most recent call last):
  File "D:\HttpRunnerManager\ApiManager\utils\operation.py", line 73, in add_module_data
    belong_project = ProjectInfo.objects.get_pro_name(belong_project, type=False)
  File "D:\HttpRunnerManager\ApiManager\managers.py", line 56, in get_pro_name
    return self.get(project_name__exact=pro_name)
  File "E:\Python35\lib\site-packages\django\db\models\manager.py", line 82, in manager_method
    return getattr(self.get_queryset(), name)(*args, **kwargs)
  File "E:\Python35\lib\site-packages\django\db\models\query.py", line 403, in get
    self.model._meta.object_name
ApiManager.models.DoesNotExist: ProjectInfo matching query does not exist.

During handling of the above exception, another exception occurred:

Traceback (most recent call last):
  File "E:\Python35\lib\site-packages\django\core\handlers\exception.py", line 35, in inner
    response = get_response(request)
  File "E:\Python35\lib\site-packages\django\core\handlers\base.py", line 128, in _get_response
    response = self.process_exception_by_middleware(e, request)
  File "E:\Python35\lib\site-packages\django\core\handlers\base.py", line 126, in _get_response
    response = wrapped_callback(request, *callback_args, **callback_kwargs)
  File "D:\HttpRunnerManager\HttpRunnerManager\activator.py", line 31, in process
    result = fun(request)
  File "D:\HttpRunnerManager\ApiManager\views.py", line 115, in add_module
    msg = module_info_logic(**module_info)
  File "D:\HttpRunnerManager\ApiManager\utils\common.py", line 135, in module_info_logic
    return add_module_data(type, **kwargs)
  File "D:\HttpRunnerManager\ApiManager\utils\operation.py", line 75, in add_module_data
    logging.error('{项目信息读取失败：{belong_project}'.format(belong_project=belong_project))
ValueError: unexpected '{' in field name
2018-04-24 15:53:25,659 [django.request:118] [exception:handle_uncaught_exception] [ERROR]- Internal Server Error: /api/add_module/
Traceback (most recent call last):
  File "D:\HttpRunnerManager\HttpRunnerManager\activator.py", line 29, in process
    result = fun(request, index)
TypeError: add_module() takes 1 positional argument but 2 were given

During handling of the above exception, another exception occurred:

Traceback (most recent call last):
  File "D:\HttpRunnerManager\ApiManager\utils\operation.py", line 73, in add_module_data
    belong_project = ProjectInfo.objects.get_pro_name(belong_project, type=False)
  File "D:\HttpRunnerManager\ApiManager\managers.py", line 56, in get_pro_name
    return self.get(project_name__exact=pro_name)
  File "E:\Python35\lib\site-packages\django\db\models\manager.py", line 82, in manager_method
    return getattr(self.get_queryset(), name)(*args, **kwargs)
  File "E:\Python35\lib\site-packages\django\db\models\query.py", line 403, in get
    self.model._meta.object_name
ApiManager.models.DoesNotExist: ProjectInfo matching query does not exist.

During handling of the above exception, another exception occurred:

Traceback (most recent call last):
  File "E:\Python35\lib\site-packages\django\core\handlers\exception.py", line 35, in inner
    response = get_response(request)
  File "E:\Python35\lib\site-packages\django\core\handlers\base.py", line 128, in _get_response
    response = self.process_exception_by_middleware(e, request)
  File "E:\Python35\lib\site-packages\django\core\handlers\base.py", line 126, in _get_response
    response = wrapped_callback(request, *callback_args, **callback_kwargs)
  File "D:\HttpRunnerManager\HttpRunnerManager\activator.py", line 31, in process
    result = fun(request)
  File "D:\HttpRunnerManager\ApiManager\views.py", line 115, in add_module
    msg = module_info_logic(**module_info)
  File "D:\HttpRunnerManager\ApiManager\utils\common.py", line 135, in module_info_logic
    return add_module_data(type, **kwargs)
  File "D:\HttpRunnerManager\ApiManager\utils\operation.py", line 75, in add_module_data
    logging.error('{项目信息读取失败：{belong_project}'.format(belong_project=belong_project))
ValueError: unexpected '{' in field name
2018-04-24 15:54:29,565 [django.request:118] [exception:handle_uncaught_exception] [ERROR]- Internal Server Error: /api/add_module/
Traceback (most recent call last):
  File "D:\HttpRunnerManager\HttpRunnerManager\activator.py", line 29, in process
    result = fun(request, index)
TypeError: add_module() takes 1 positional argument but 2 were given

During handling of the above exception, another exception occurred:

Traceback (most recent call last):
  File "D:\HttpRunnerManager\ApiManager\utils\operation.py", line 73, in add_module_data
    belong_project = ProjectInfo.objects.get_pro_name(belong_project, type=False)
  File "D:\HttpRunnerManager\ApiManager\managers.py", line 56, in get_pro_name
    return self.get(project_name__exact=pro_name)
  File "E:\Python35\lib\site-packages\django\db\models\manager.py", line 82, in manager_method
    return getattr(self.get_queryset(), name)(*args, **kwargs)
  File "E:\Python35\lib\site-packages\django\db\models\query.py", line 403, in get
    self.model._meta.object_name
ApiManager.models.DoesNotExist: ProjectInfo matching query does not exist.

During handling of the above exception, another exception occurred:

Traceback (most recent call last):
  File "E:\Python35\lib\site-packages\django\core\handlers\exception.py", line 35, in inner
    response = get_response(request)
  File "E:\Python35\lib\site-packages\django\core\handlers\base.py", line 128, in _get_response
    response = self.process_exception_by_middleware(e, request)
  File "E:\Python35\lib\site-packages\django\core\handlers\base.py", line 126, in _get_response
    response = wrapped_callback(request, *callback_args, **callback_kwargs)
  File "D:\HttpRunnerManager\HttpRunnerManager\activator.py", line 31, in process
    result = fun(request)
  File "D:\HttpRunnerManager\ApiManager\views.py", line 115, in add_module
    msg = module_info_logic(**module_info)
  File "D:\HttpRunnerManager\ApiManager\utils\common.py", line 135, in module_info_logic
    return add_module_data(type, **kwargs)
  File "D:\HttpRunnerManager\ApiManager\utils\operation.py", line 75, in add_module_data
    logging.error('{项目信息读取失败：{belong_project}'.format(belong_project=belong_project))
ValueError: unexpected '{' in field name
2018-04-24 16:04:54,917 [HttpRunnerManager:47] [operation:add_project_data] [INFO]- 项目添加成功：{'dev_user': 'dfda', 'other_desc': '', 'project_name': 'fd', 'test_user': 'ddfa', 'simple_desc': '', 'responsible_name': 'da', 'publish_app': 'fda'}
2018-04-24 16:17:38,518 [HttpRunnerManager:61] [operation:add_project_data] [INFO]- 更新成功：{}
2018-04-24 16:17:41,282 [HttpRunnerManager:61] [operation:add_project_data] [INFO]- 更新成功：{}
2018-04-24 16:21:38,821 [HttpRunnerManager:59] [operation:add_project_data] [INFO]- 更新成功：{'publish_app': 'feaw', 'dev_user': 'fda', 'responsible_name': 'fdfd', 'other_desc': 'fda', 'project_name': 'fdaffdfr', 'test_user': 'fddf', 'simple_desc': 'fda'}
2018-04-24 16:25:07,316 [HttpRunnerManager:102] [operation:add_module_data] [INFO]- 模块更新成功：{'simple_desc': '', 'module_name': '11', 'test_user': '11', 'other_desc': ''}
2018-04-24 16:25:49,375 [HttpRunnerManager:89] [operation:add_module_data] [INFO]- 模块添加成功：{'simple_desc': '', 'module_name': 'd', 'test_user': 'd', 'other_desc': '', 'belong_project': <ProjectInfo: ProjectInfo object (4)>}
2018-04-24 16:26:00,319 [HttpRunnerManager:179] [operation:change_status] [INFO]- 4状态已更改！
2018-04-24 16:26:05,540 [HttpRunnerManager:179] [operation:change_status] [INFO]- 5状态已更改！
2018-04-24 16:26:42,414 [django.request:118] [exception:handle_uncaught_exception] [ERROR]- Internal Server Error: /api/add_config/
Traceback (most recent call last):
  File "D:\HttpRunnerManager\HttpRunnerManager\activator.py", line 29, in process
    result = fun(request, index)
TypeError: add_config() takes 1 positional argument but 2 were given

During handling of the above exception, another exception occurred:

Traceback (most recent call last):
  File "E:\Python35\lib\site-packages\django\db\models\sql\query.py", line 1683, in add_fields
    join_info = self.setup_joins(name.split(LOOKUP_SEP), opts, alias, allow_many=allow_m2m)
  File "E:\Python35\lib\site-packages\django\db\models\sql\query.py", line 1448, in setup_joins
    names, opts, allow_many, fail_on_missing=True)
  File "E:\Python35\lib\site-packages\django\db\models\sql\query.py", line 1379, in names_to_path
    "Choices are: %s" % (name, ", ".join(available)))
django.core.exceptions.FieldError: Cannot resolve keyword 'pro_name' into field. Choices are: create_time, dev_user, id, moduleinfo, other_desc, project_name, publish_app, responsible_name, simple_desc, test_user, update_time

During handling of the above exception, another exception occurred:

Traceback (most recent call last):
  File "E:\Python35\lib\site-packages\django\core\handlers\exception.py", line 35, in inner
    response = get_response(request)
  File "E:\Python35\lib\site-packages\django\core\handlers\base.py", line 128, in _get_response
    response = self.process_exception_by_middleware(e, request)
  File "E:\Python35\lib\site-packages\django\core\handlers\base.py", line 126, in _get_response
    response = wrapped_callback(request, *callback_args, **callback_kwargs)
  File "D:\HttpRunnerManager\HttpRunnerManager\activator.py", line 31, in process
    result = fun(request)
  File "D:\HttpRunnerManager\ApiManager\views.py", line 162, in add_config
    'project': ProjectInfo.objects.all().values('pro_name').order_by('-create_time')
  File "E:\Python35\lib\site-packages\django\db\models\query.py", line 742, in values
    clone = self._values(*fields, **expressions)
  File "E:\Python35\lib\site-packages\django\db\models\query.py", line 737, in _values
    clone.query.set_values(fields)
  File "E:\Python35\lib\site-packages\django\db\models\sql\query.py", line 1935, in set_values
    self.add_fields(field_names, True)
  File "E:\Python35\lib\site-packages\django\db\models\sql\query.py", line 1706, in add_fields
    "Choices are: %s" % (name, ", ".join(names)))
django.core.exceptions.FieldError: Cannot resolve keyword 'pro_name' into field. Choices are: create_time, dev_user, id, moduleinfo, other_desc, project_name, publish_app, responsible_name, simple_desc, test_user, update_time
2018-04-24 16:52:48,072 [HttpRunnerManager:89] [operation:add_module_data] [INFO]- 模块添加成功：{'test_user': '发', 'module_name': '发发 ', 'other_desc': '', 'belong_project': <ProjectInfo: ProjectInfo object (4)>, 'simple_desc': ''}
2018-04-24 16:55:10,301 [HttpRunnerManager:102] [operation:add_module_data] [INFO]- 模块更新成功：{'module_name': '发发 ', 'other_desc': '', 'simple_desc': '', 'test_user': '发'}
2018-04-24 16:55:15,486 [HttpRunnerManager:102] [operation:add_module_data] [INFO]- 模块更新成功：{'module_name': '发发 的', 'other_desc': '', 'simple_desc': '', 'test_user': '发'}
2018-04-24 17:30:33,518 [django.request:118] [exception:handle_uncaught_exception] [ERROR]- Internal Server Error: /api/project_list/1/
Traceback (most recent call last):
  File "E:\Python35\lib\site-packages\django\core\handlers\exception.py", line 35, in inner
    response = get_response(request)
  File "E:\Python35\lib\site-packages\django\core\handlers\base.py", line 128, in _get_response
    response = self.process_exception_by_middleware(e, request)
  File "E:\Python35\lib\site-packages\django\core\handlers\base.py", line 126, in _get_response
    response = wrapped_callback(request, *callback_args, **callback_kwargs)
  File "D:\HttpRunnerManager\HttpRunnerManager\activator.py", line 29, in process
    result = fun(request, index)
  File "D:\HttpRunnerManager\ApiManager\views.py", line 242, in project_list
    return render_to_response('project_list.html', manage_info)
  File "E:\Python35\lib\site-packages\django\shortcuts.py", line 27, in render_to_response
    content = loader.render_to_string(template_name, context, using=using)
  File "E:\Python35\lib\site-packages\django\template\loader.py", line 61, in render_to_string
    template = get_template(template_name, using=using)
  File "E:\Python35\lib\site-packages\django\template\loader.py", line 15, in get_template
    return engine.get_template(template_name)
  File "E:\Python35\lib\site-packages\django\template\backends\django.py", line 34, in get_template
    return Template(self.engine.get_template(template_name), self)
  File "E:\Python35\lib\site-packages\django\template\engine.py", line 144, in get_template
    template, origin = self.find_template(template_name)
  File "E:\Python35\lib\site-packages\django\template\engine.py", line 126, in find_template
    template = loader.get_template(name, skip=skip)
  File "E:\Python35\lib\site-packages\django\template\loaders\base.py", line 30, in get_template
    contents, origin, origin.template_name, self.engine,
  File "E:\Python35\lib\site-packages\django\template\base.py", line 160, in __init__
    self.nodelist = self.compile_nodelist()
  File "E:\Python35\lib\site-packages\django\template\base.py", line 198, in compile_nodelist
    return parser.parse()
  File "E:\Python35\lib\site-packages\django\template\base.py", line 483, in parse
    raise self.error(token, e)
  File "E:\Python35\lib\site-packages\django\template\base.py", line 481, in parse
    compiled_result = compile_func(self, token)
  File "E:\Python35\lib\site-packages\django\template\loader_tags.py", line 290, in do_extends
    nodelist = parser.parse()
  File "E:\Python35\lib\site-packages\django\template\base.py", line 483, in parse
    raise self.error(token, e)
  File "E:\Python35\lib\site-packages\django\template\base.py", line 481, in parse
    compiled_result = compile_func(self, token)
  File "E:\Python35\lib\site-packages\django\template\loader_tags.py", line 233, in do_block
    nodelist = parser.parse(('endblock',))
  File "E:\Python35\lib\site-packages\django\template\base.py", line 483, in parse
    raise self.error(token, e)
  File "E:\Python35\lib\site-packages\django\template\base.py", line 481, in parse
    compiled_result = compile_func(self, token)
  File "E:\Python35\lib\site-packages\django\template\defaulttags.py", line 815, in do_for
    nodelist_loop = parser.parse(('empty', 'endfor',))
  File "E:\Python35\lib\site-packages\django\template\base.py", line 454, in parse
    raise self.error(token, e)
  File "E:\Python35\lib\site-packages\django\template\base.py", line 452, in parse
    filter_expression = self.compile_filter(token.contents)
  File "E:\Python35\lib\site-packages\django\template\base.py", line 568, in compile_filter
    return FilterExpression(token, self)
  File "E:\Python35\lib\site-packages\django\template\base.py", line 668, in __init__
    "from '%s'" % (token[upto:], token))
django.template.exceptions.TemplateSyntaxError: Could not parse the remainder: '{{ foo.project_name' from 'sum.pop.{{ foo.project_name'
2018-04-24 17:50:07,736 [django.request:118] [exception:handle_uncaught_exception] [ERROR]- Internal Server Error: /api/project_list/1/
Traceback (most recent call last):
  File "D:\HttpRunnerManager\HttpRunnerManager\activator.py", line 29, in process
    result = fun(request, index)
  File "D:\HttpRunnerManager\ApiManager\views.py", line 234, in project_list
    ProjectInfo, filter_query, '/api/project_list/', id)
  File "D:\HttpRunnerManager\ApiManager\utils\pagination.py", line 130, in get_pager_info
    sum.setdefault(pro_name, module_count+'/'+test_count+'/'+config_count)
TypeError: unsupported operand type(s) for +: 'int' and 'str'

During handling of the above exception, another exception occurred:

Traceback (most recent call last):
  File "E:\Python35\lib\site-packages\django\core\handlers\exception.py", line 35, in inner
    response = get_response(request)
  File "E:\Python35\lib\site-packages\django\core\handlers\base.py", line 128, in _get_response
    response = self.process_exception_by_middleware(e, request)
  File "E:\Python35\lib\site-packages\django\core\handlers\base.py", line 126, in _get_response
    response = wrapped_callback(request, *callback_args, **callback_kwargs)
  File "D:\HttpRunnerManager\HttpRunnerManager\activator.py", line 31, in process
    result = fun(request)
TypeError: project_list() missing 1 required positional argument: 'id'
2018-04-24 17:50:26,853 [django.request:118] [exception:handle_uncaught_exception] [ERROR]- Internal Server Error: /api/project_list/1/
Traceback (most recent call last):
  File "D:\HttpRunnerManager\HttpRunnerManager\activator.py", line 29, in process
    result = fun(request, index)
  File "D:\HttpRunnerManager\ApiManager\views.py", line 234, in project_list
    ProjectInfo, filter_query, '/api/project_list/', id)
  File "D:\HttpRunnerManager\ApiManager\utils\pagination.py", line 130, in get_pager_info
    sum.setdefault(pro_name, module_count+'/'+test_count+'/'+config_count)
TypeError: unsupported operand type(s) for +: 'int' and 'str'

During handling of the above exception, another exception occurred:

Traceback (most recent call last):
  File "E:\Python35\lib\site-packages\django\core\handlers\exception.py", line 35, in inner
    response = get_response(request)
  File "E:\Python35\lib\site-packages\django\core\handlers\base.py", line 128, in _get_response
    response = self.process_exception_by_middleware(e, request)
  File "E:\Python35\lib\site-packages\django\core\handlers\base.py", line 126, in _get_response
    response = wrapped_callback(request, *callback_args, **callback_kwargs)
  File "D:\HttpRunnerManager\HttpRunnerManager\activator.py", line 31, in process
    result = fun(request)
TypeError: project_list() missing 1 required positional argument: 'id'
2018-04-24 17:50:27,866 [django.request:118] [exception:handle_uncaught_exception] [ERROR]- Internal Server Error: /api/project_list/1/
Traceback (most recent call last):
  File "D:\HttpRunnerManager\HttpRunnerManager\activator.py", line 29, in process
    result = fun(request, index)
  File "D:\HttpRunnerManager\ApiManager\views.py", line 234, in project_list
    ProjectInfo, filter_query, '/api/project_list/', id)
  File "D:\HttpRunnerManager\ApiManager\utils\pagination.py", line 130, in get_pager_info
    sum.setdefault(pro_name, module_count+'/'+test_count+'/'+config_count)
TypeError: unsupported operand type(s) for +: 'int' and 'str'

During handling of the above exception, another exception occurred:

Traceback (most recent call last):
  File "E:\Python35\lib\site-packages\django\core\handlers\exception.py", line 35, in inner
    response = get_response(request)
  File "E:\Python35\lib\site-packages\django\core\handlers\base.py", line 128, in _get_response
    response = self.process_exception_by_middleware(e, request)
  File "E:\Python35\lib\site-packages\django\core\handlers\base.py", line 126, in _get_response
    response = wrapped_callback(request, *callback_args, **callback_kwargs)
  File "D:\HttpRunnerManager\HttpRunnerManager\activator.py", line 31, in process
    result = fun(request)
TypeError: project_list() missing 1 required positional argument: 'id'
2018-04-24 17:51:16,612 [django.request:118] [exception:handle_uncaught_exception] [ERROR]- Internal Server Error: /api/project_list/1/
Traceback (most recent call last):
  File "D:\HttpRunnerManager\HttpRunnerManager\activator.py", line 29, in process
    result = fun(request, index)
  File "D:\HttpRunnerManager\ApiManager\views.py", line 234, in project_list
    ProjectInfo, filter_query, '/api/project_list/', id)
  File "D:\HttpRunnerManager\ApiManager\utils\pagination.py", line 130, in get_pager_info
    sum.setdefault(pro_name, module_count+'/'+test_count+'/'+config_count)
TypeError: unsupported operand type(s) for +: 'int' and 'str'

During handling of the above exception, another exception occurred:

Traceback (most recent call last):
  File "E:\Python35\lib\site-packages\django\core\handlers\exception.py", line 35, in inner
    response = get_response(request)
  File "E:\Python35\lib\site-packages\django\core\handlers\base.py", line 128, in _get_response
    response = self.process_exception_by_middleware(e, request)
  File "E:\Python35\lib\site-packages\django\core\handlers\base.py", line 126, in _get_response
    response = wrapped_callback(request, *callback_args, **callback_kwargs)
  File "D:\HttpRunnerManager\HttpRunnerManager\activator.py", line 31, in process
    result = fun(request)
TypeError: project_list() missing 1 required positional argument: 'id'
2018-04-24 17:54:08,496 [django.request:118] [exception:handle_uncaught_exception] [ERROR]- Internal Server Error: /api/project_list/1/
Traceback (most recent call last):
  File "D:\HttpRunnerManager\HttpRunnerManager\activator.py", line 29, in process
    result = fun(request, index)
  File "D:\HttpRunnerManager\ApiManager\views.py", line 234, in project_list
    ProjectInfo, filter_query, '/api/project_list/', id)
  File "D:\HttpRunnerManager\ApiManager\utils\pagination.py", line 130, in get_pager_info
    sum.setdefault(pro_name, module_count+'/')
TypeError: unsupported operand type(s) for +: 'int' and 'str'

During handling of the above exception, another exception occurred:

Traceback (most recent call last):
  File "E:\Python35\lib\site-packages\django\core\handlers\exception.py", line 35, in inner
    response = get_response(request)
  File "E:\Python35\lib\site-packages\django\core\handlers\base.py", line 128, in _get_response
    response = self.process_exception_by_middleware(e, request)
  File "E:\Python35\lib\site-packages\django\core\handlers\base.py", line 126, in _get_response
    response = wrapped_callback(request, *callback_args, **callback_kwargs)
  File "D:\HttpRunnerManager\HttpRunnerManager\activator.py", line 31, in process
    result = fun(request)
TypeError: project_list() missing 1 required positional argument: 'id'
2018-04-24 18:18:38,692 [django.request:118] [exception:handle_uncaught_exception] [ERROR]- Internal Server Error: /api/module_list/1/
Traceback (most recent call last):
  File "E:\Python35\lib\site-packages\django\core\handlers\exception.py", line 35, in inner
    response = get_response(request)
  File "E:\Python35\lib\site-packages\django\core\handlers\base.py", line 128, in _get_response
    response = self.process_exception_by_middleware(e, request)
  File "E:\Python35\lib\site-packages\django\core\handlers\base.py", line 126, in _get_response
    response = wrapped_callback(request, *callback_args, **callback_kwargs)
  File "D:\HttpRunnerManager\HttpRunnerManager\activator.py", line 29, in process
    result = fun(request, index)
  File "D:\HttpRunnerManager\ApiManager\views.py", line 276, in module_list
    return render_to_response('module_list.html', manage_info)
  File "E:\Python35\lib\site-packages\django\shortcuts.py", line 27, in render_to_response
    content = loader.render_to_string(template_name, context, using=using)
  File "E:\Python35\lib\site-packages\django\template\loader.py", line 61, in render_to_string
    template = get_template(template_name, using=using)
  File "E:\Python35\lib\site-packages\django\template\loader.py", line 15, in get_template
    return engine.get_template(template_name)
  File "E:\Python35\lib\site-packages\django\template\backends\django.py", line 34, in get_template
    return Template(self.engine.get_template(template_name), self)
  File "E:\Python35\lib\site-packages\django\template\engine.py", line 144, in get_template
    template, origin = self.find_template(template_name)
  File "E:\Python35\lib\site-packages\django\template\engine.py", line 126, in find_template
    template = loader.get_template(name, skip=skip)
  File "E:\Python35\lib\site-packages\django\template\loaders\base.py", line 30, in get_template
    contents, origin, origin.template_name, self.engine,
  File "E:\Python35\lib\site-packages\django\template\base.py", line 160, in __init__
    self.nodelist = self.compile_nodelist()
  File "E:\Python35\lib\site-packages\django\template\base.py", line 198, in compile_nodelist
    return parser.parse()
  File "E:\Python35\lib\site-packages\django\template\base.py", line 483, in parse
    raise self.error(token, e)
  File "E:\Python35\lib\site-packages\django\template\base.py", line 481, in parse
    compiled_result = compile_func(self, token)
  File "E:\Python35\lib\site-packages\django\template\loader_tags.py", line 290, in do_extends
    nodelist = parser.parse()
  File "E:\Python35\lib\site-packages\django\template\base.py", line 483, in parse
    raise self.error(token, e)
  File "E:\Python35\lib\site-packages\django\template\base.py", line 481, in parse
    compiled_result = compile_func(self, token)
  File "E:\Python35\lib\site-packages\django\template\loader_tags.py", line 233, in do_block
    nodelist = parser.parse(('endblock',))
  File "E:\Python35\lib\site-packages\django\template\base.py", line 483, in parse
    raise self.error(token, e)
  File "E:\Python35\lib\site-packages\django\template\base.py", line 481, in parse
    compiled_result = compile_func(self, token)
  File "E:\Python35\lib\site-packages\django\template\defaulttags.py", line 815, in do_for
    nodelist_loop = parser.parse(('empty', 'endfor',))
  File "E:\Python35\lib\site-packages\django\template\base.py", line 483, in parse
    raise self.error(token, e)
  File "E:\Python35\lib\site-packages\django\template\base.py", line 481, in parse
    compiled_result = compile_func(self, token)
  File "E:\Python35\lib\site-packages\django\template\defaulttags.py", line 815, in do_for
    nodelist_loop = parser.parse(('empty', 'endfor',))
  File "E:\Python35\lib\site-packages\django\template\base.py", line 483, in parse
    raise self.error(token, e)
  File "E:\Python35\lib\site-packages\django\template\base.py", line 481, in parse
    compiled_result = compile_func(self, token)
  File "E:\Python35\lib\site-packages\django\template\defaulttags.py", line 859, in ifequal
    return do_ifequal(parser, token, False)
  File "E:\Python35\lib\site-packages\django\template\defaulttags.py", line 828, in do_ifequal
    raise TemplateSyntaxError("%r takes two arguments" % bits[0])
django.template.exceptions.TemplateSyntaxError: 'ifequal' takes two arguments
2018-04-25 09:57:37,056 [HttpRunnerManager:29] [views:login] [INFO]- yinquanwang 登录成功
2018-04-25 10:03:38,120 [django.request:118] [exception:handle_uncaught_exception] [ERROR]- Internal Server Error: /api/module_list/1/
Traceback (most recent call last):
  File "E:\Python35\lib\site-packages\django\core\handlers\exception.py", line 35, in inner
    response = get_response(request)
  File "E:\Python35\lib\site-packages\django\core\handlers\base.py", line 128, in _get_response
    response = self.process_exception_by_middleware(e, request)
  File "E:\Python35\lib\site-packages\django\core\handlers\base.py", line 126, in _get_response
    response = wrapped_callback(request, *callback_args, **callback_kwargs)
  File "D:\HttpRunnerManager\HttpRunnerManager\activator.py", line 29, in process
    result = fun(request, index)
  File "D:\HttpRunnerManager\ApiManager\views.py", line 278, in module_list
    return render_to_response('module_list.html', manage_info)
  File "E:\Python35\lib\site-packages\django\shortcuts.py", line 27, in render_to_response
    content = loader.render_to_string(template_name, context, using=using)
  File "E:\Python35\lib\site-packages\django\template\loader.py", line 61, in render_to_string
    template = get_template(template_name, using=using)
  File "E:\Python35\lib\site-packages\django\template\loader.py", line 15, in get_template
    return engine.get_template(template_name)
  File "E:\Python35\lib\site-packages\django\template\backends\django.py", line 34, in get_template
    return Template(self.engine.get_template(template_name), self)
  File "E:\Python35\lib\site-packages\django\template\engine.py", line 144, in get_template
    template, origin = self.find_template(template_name)
  File "E:\Python35\lib\site-packages\django\template\engine.py", line 126, in find_template
    template = loader.get_template(name, skip=skip)
  File "E:\Python35\lib\site-packages\django\template\loaders\base.py", line 30, in get_template
    contents, origin, origin.template_name, self.engine,
  File "E:\Python35\lib\site-packages\django\template\base.py", line 160, in __init__
    self.nodelist = self.compile_nodelist()
  File "E:\Python35\lib\site-packages\django\template\base.py", line 198, in compile_nodelist
    return parser.parse()
  File "E:\Python35\lib\site-packages\django\template\base.py", line 483, in parse
    raise self.error(token, e)
  File "E:\Python35\lib\site-packages\django\template\base.py", line 481, in parse
    compiled_result = compile_func(self, token)
  File "E:\Python35\lib\site-packages\django\template\loader_tags.py", line 290, in do_extends
    nodelist = parser.parse()
  File "E:\Python35\lib\site-packages\django\template\base.py", line 483, in parse
    raise self.error(token, e)
  File "E:\Python35\lib\site-packages\django\template\base.py", line 481, in parse
    compiled_result = compile_func(self, token)
  File "E:\Python35\lib\site-packages\django\template\loader_tags.py", line 233, in do_block
    nodelist = parser.parse(('endblock',))
  File "E:\Python35\lib\site-packages\django\template\base.py", line 483, in parse
    raise self.error(token, e)
  File "E:\Python35\lib\site-packages\django\template\base.py", line 481, in parse
    compiled_result = compile_func(self, token)
  File "E:\Python35\lib\site-packages\django\template\defaulttags.py", line 815, in do_for
    nodelist_loop = parser.parse(('empty', 'endfor',))
  File "E:\Python35\lib\site-packages\django\template\base.py", line 454, in parse
    raise self.error(token, e)
  File "E:\Python35\lib\site-packages\django\template\base.py", line 452, in parse
    filter_expression = self.compile_filter(token.contents)
  File "E:\Python35\lib\site-packages\django\template\base.py", line 568, in compile_filter
    return FilterExpression(token, self)
  File "E:\Python35\lib\site-packages\django\template\base.py", line 663, in __init__
    self.args_check(filter_name, filter_func, args)
  File "E:\Python35\lib\site-packages\django\template\base.py", line 723, in args_check
    (name, alen - dlen, plen))
django.template.exceptions.TemplateSyntaxError: join requires 2 arguments, 1 provided
2018-04-25 10:03:54,632 [django.request:118] [exception:handle_uncaught_exception] [ERROR]- Internal Server Error: /api/module_list/1/
Traceback (most recent call last):
  File "E:\Python35\lib\site-packages\django\core\handlers\exception.py", line 35, in inner
    response = get_response(request)
  File "E:\Python35\lib\site-packages\django\core\handlers\base.py", line 128, in _get_response
    response = self.process_exception_by_middleware(e, request)
  File "E:\Python35\lib\site-packages\django\core\handlers\base.py", line 126, in _get_response
    response = wrapped_callback(request, *callback_args, **callback_kwargs)
  File "D:\HttpRunnerManager\HttpRunnerManager\activator.py", line 29, in process
    result = fun(request, index)
  File "D:\HttpRunnerManager\ApiManager\views.py", line 278, in module_list
    return render_to_response('module_list.html', manage_info)
  File "E:\Python35\lib\site-packages\django\shortcuts.py", line 27, in render_to_response
    content = loader.render_to_string(template_name, context, using=using)
  File "E:\Python35\lib\site-packages\django\template\loader.py", line 61, in render_to_string
    template = get_template(template_name, using=using)
  File "E:\Python35\lib\site-packages\django\template\loader.py", line 15, in get_template
    return engine.get_template(template_name)
  File "E:\Python35\lib\site-packages\django\template\backends\django.py", line 34, in get_template
    return Template(self.engine.get_template(template_name), self)
  File "E:\Python35\lib\site-packages\django\template\engine.py", line 144, in get_template
    template, origin = self.find_template(template_name)
  File "E:\Python35\lib\site-packages\django\template\engine.py", line 126, in find_template
    template = loader.get_template(name, skip=skip)
  File "E:\Python35\lib\site-packages\django\template\loaders\base.py", line 30, in get_template
    contents, origin, origin.template_name, self.engine,
  File "E:\Python35\lib\site-packages\django\template\base.py", line 160, in __init__
    self.nodelist = self.compile_nodelist()
  File "E:\Python35\lib\site-packages\django\template\base.py", line 198, in compile_nodelist
    return parser.parse()
  File "E:\Python35\lib\site-packages\django\template\base.py", line 483, in parse
    raise self.error(token, e)
  File "E:\Python35\lib\site-packages\django\template\base.py", line 481, in parse
    compiled_result = compile_func(self, token)
  File "E:\Python35\lib\site-packages\django\template\loader_tags.py", line 290, in do_extends
    nodelist = parser.parse()
  File "E:\Python35\lib\site-packages\django\template\base.py", line 483, in parse
    raise self.error(token, e)
  File "E:\Python35\lib\site-packages\django\template\base.py", line 481, in parse
    compiled_result = compile_func(self, token)
  File "E:\Python35\lib\site-packages\django\template\loader_tags.py", line 233, in do_block
    nodelist = parser.parse(('endblock',))
  File "E:\Python35\lib\site-packages\django\template\base.py", line 483, in parse
    raise self.error(token, e)
  File "E:\Python35\lib\site-packages\django\template\base.py", line 481, in parse
    compiled_result = compile_func(self, token)
  File "E:\Python35\lib\site-packages\django\template\defaulttags.py", line 815, in do_for
    nodelist_loop = parser.parse(('empty', 'endfor',))
  File "E:\Python35\lib\site-packages\django\template\base.py", line 454, in parse
    raise self.error(token, e)
  File "E:\Python35\lib\site-packages\django\template\base.py", line 452, in parse
    filter_expression = self.compile_filter(token.contents)
  File "E:\Python35\lib\site-packages\django\template\base.py", line 568, in compile_filter
    return FilterExpression(token, self)
  File "E:\Python35\lib\site-packages\django\template\base.py", line 663, in __init__
    self.args_check(filter_name, filter_func, args)
  File "E:\Python35\lib\site-packages\django\template\base.py", line 723, in args_check
    (name, alen - dlen, plen))
django.template.exceptions.TemplateSyntaxError: join requires 2 arguments, 1 provided
2018-04-25 10:07:25,373 [django.request:118] [exception:handle_uncaught_exception] [ERROR]- Internal Server Error: /api/module_list/1/
Traceback (most recent call last):
  File "E:\Python35\lib\site-packages\django\core\handlers\exception.py", line 35, in inner
    response = get_response(request)
  File "E:\Python35\lib\site-packages\django\core\handlers\base.py", line 128, in _get_response
    response = self.process_exception_by_middleware(e, request)
  File "E:\Python35\lib\site-packages\django\core\handlers\base.py", line 126, in _get_response
    response = wrapped_callback(request, *callback_args, **callback_kwargs)
  File "D:\HttpRunnerManager\HttpRunnerManager\activator.py", line 29, in process
    result = fun(request, index)
  File "D:\HttpRunnerManager\ApiManager\views.py", line 278, in module_list
    return render_to_response('module_list.html', manage_info)
  File "E:\Python35\lib\site-packages\django\shortcuts.py", line 27, in render_to_response
    content = loader.render_to_string(template_name, context, using=using)
  File "E:\Python35\lib\site-packages\django\template\loader.py", line 61, in render_to_string
    template = get_template(template_name, using=using)
  File "E:\Python35\lib\site-packages\django\template\loader.py", line 15, in get_template
    return engine.get_template(template_name)
  File "E:\Python35\lib\site-packages\django\template\backends\django.py", line 34, in get_template
    return Template(self.engine.get_template(template_name), self)
  File "E:\Python35\lib\site-packages\django\template\engine.py", line 144, in get_template
    template, origin = self.find_template(template_name)
  File "E:\Python35\lib\site-packages\django\template\engine.py", line 126, in find_template
    template = loader.get_template(name, skip=skip)
  File "E:\Python35\lib\site-packages\django\template\loaders\base.py", line 30, in get_template
    contents, origin, origin.template_name, self.engine,
  File "E:\Python35\lib\site-packages\django\template\base.py", line 160, in __init__
    self.nodelist = self.compile_nodelist()
  File "E:\Python35\lib\site-packages\django\template\base.py", line 198, in compile_nodelist
    return parser.parse()
  File "E:\Python35\lib\site-packages\django\template\base.py", line 483, in parse
    raise self.error(token, e)
  File "E:\Python35\lib\site-packages\django\template\base.py", line 481, in parse
    compiled_result = compile_func(self, token)
  File "E:\Python35\lib\site-packages\django\template\loader_tags.py", line 290, in do_extends
    nodelist = parser.parse()
  File "E:\Python35\lib\site-packages\django\template\base.py", line 483, in parse
    raise self.error(token, e)
  File "E:\Python35\lib\site-packages\django\template\base.py", line 481, in parse
    compiled_result = compile_func(self, token)
  File "E:\Python35\lib\site-packages\django\template\loader_tags.py", line 233, in do_block
    nodelist = parser.parse(('endblock',))
  File "E:\Python35\lib\site-packages\django\template\base.py", line 483, in parse
    raise self.error(token, e)
  File "E:\Python35\lib\site-packages\django\template\base.py", line 481, in parse
    compiled_result = compile_func(self, token)
  File "E:\Python35\lib\site-packages\django\template\defaulttags.py", line 815, in do_for
    nodelist_loop = parser.parse(('empty', 'endfor',))
  File "E:\Python35\lib\site-packages\django\template\base.py", line 454, in parse
    raise self.error(token, e)
  File "E:\Python35\lib\site-packages\django\template\base.py", line 452, in parse
    filter_expression = self.compile_filter(token.contents)
  File "E:\Python35\lib\site-packages\django\template\base.py", line 568, in compile_filter
    return FilterExpression(token, self)
  File "E:\Python35\lib\site-packages\django\template\base.py", line 663, in __init__
    self.args_check(filter_name, filter_func, args)
  File "E:\Python35\lib\site-packages\django\template\base.py", line 723, in args_check
    (name, alen - dlen, plen))
django.template.exceptions.TemplateSyntaxError: join requires 2 arguments, 1 provided
2018-04-25 10:22:12,731 [django.request:118] [exception:handle_uncaught_exception] [ERROR]- Internal Server Error: /api/run_test/
Traceback (most recent call last):
  File "D:\HttpRunnerManager\HttpRunnerManager\activator.py", line 29, in process
    result = fun(request, index)
TypeError: run_test() takes 1 positional argument but 2 were given

During handling of the above exception, another exception occurred:

Traceback (most recent call last):
  File "E:\Python35\lib\site-packages\django\core\handlers\exception.py", line 35, in inner
    response = get_response(request)
  File "E:\Python35\lib\site-packages\django\core\handlers\base.py", line 128, in _get_response
    response = self.process_exception_by_middleware(e, request)
  File "E:\Python35\lib\site-packages\django\core\handlers\base.py", line 126, in _get_response
    response = wrapped_callback(request, *callback_args, **callback_kwargs)
  File "D:\HttpRunnerManager\HttpRunnerManager\activator.py", line 31, in process
    result = fun(request)
  File "D:\HttpRunnerManager\ApiManager\views.py", line 185, in run_test
    test_lists = run_by_project(id)
  File "D:\HttpRunnerManager\ApiManager\utils\runner.py", line 47, in run_by_project
    obj = ProjectInfo.objects.get(id=id, status=1)
  File "E:\Python35\lib\site-packages\django\db\models\manager.py", line 82, in manager_method
    return getattr(self.get_queryset(), name)(*args, **kwargs)
  File "E:\Python35\lib\site-packages\django\db\models\query.py", line 394, in get
    clone = self.filter(*args, **kwargs)
  File "E:\Python35\lib\site-packages\django\db\models\query.py", line 836, in filter
    return self._filter_or_exclude(False, *args, **kwargs)
  File "E:\Python35\lib\site-packages\django\db\models\query.py", line 854, in _filter_or_exclude
    clone.query.add_q(Q(*args, **kwargs))
  File "E:\Python35\lib\site-packages\django\db\models\sql\query.py", line 1253, in add_q
    clause, _ = self._add_q(q_object, self.used_aliases)
  File "E:\Python35\lib\site-packages\django\db\models\sql\query.py", line 1277, in _add_q
    split_subq=split_subq,
  File "E:\Python35\lib\site-packages\django\db\models\sql\query.py", line 1153, in build_filter
    lookups, parts, reffed_expression = self.solve_lookup_type(arg)
  File "E:\Python35\lib\site-packages\django\db\models\sql\query.py", line 1015, in solve_lookup_type
    _, field, _, lookup_parts = self.names_to_path(lookup_splitted, self.get_meta())
  File "E:\Python35\lib\site-packages\django\db\models\sql\query.py", line 1379, in names_to_path
    "Choices are: %s" % (name, ", ".join(available)))
django.core.exceptions.FieldError: Cannot resolve keyword 'status' into field. Choices are: create_time, dev_user, id, moduleinfo, other_desc, project_name, publish_app, responsible_name, simple_desc, test_user, update_time
2018-04-25 10:33:16,230 [HttpRunnerManager:29] [views:login] [INFO]- yinquanwang 登录成功
2018-04-25 10:56:38,155 [django.request:118] [exception:handle_uncaught_exception] [ERROR]- Internal Server Error: /api/module_list/1/
Traceback (most recent call last):
  File "E:\Python35\lib\site-packages\django\core\handlers\exception.py", line 35, in inner
    response = get_response(request)
  File "E:\Python35\lib\site-packages\django\core\handlers\base.py", line 128, in _get_response
    response = self.process_exception_by_middleware(e, request)
  File "E:\Python35\lib\site-packages\django\core\handlers\base.py", line 126, in _get_response
    response = wrapped_callback(request, *callback_args, **callback_kwargs)
  File "D:\HttpRunnerManager\HttpRunnerManager\activator.py", line 29, in process
    result = fun(request, index)
  File "D:\HttpRunnerManager\ApiManager\views.py", line 270, in module_list
    ModuleInfo, filter_query, '/api/module_list/', id)
  File "D:\HttpRunnerManager\ApiManager\utils\pagination.py", line 104, in get_pager_info
    obj = obj.filter(module_name__contains=name).filter(test_user__contains=user)
  File "E:\Python35\lib\site-packages\django\db\models\manager.py", line 82, in manager_method
    return getattr(self.get_queryset(), name)(*args, **kwargs)
  File "E:\Python35\lib\site-packages\django\db\models\query.py", line 836, in filter
    return self._filter_or_exclude(False, *args, **kwargs)
  File "E:\Python35\lib\site-packages\django\db\models\query.py", line 854, in _filter_or_exclude
    clone.query.add_q(Q(*args, **kwargs))
  File "E:\Python35\lib\site-packages\django\db\models\sql\query.py", line 1253, in add_q
    clause, _ = self._add_q(q_object, self.used_aliases)
  File "E:\Python35\lib\site-packages\django\db\models\sql\query.py", line 1277, in _add_q
    split_subq=split_subq,
  File "E:\Python35\lib\site-packages\django\db\models\sql\query.py", line 1215, in build_filter
    condition = self.build_lookup(lookups, col, value)
  File "E:\Python35\lib\site-packages\django\db\models\sql\query.py", line 1090, in build_lookup
    raise ValueError("Cannot use None as a query value")
ValueError: Cannot use None as a query value
2018-04-25 11:09:28,161 [django.request:118] [exception:handle_uncaught_exception] [ERROR]- Internal Server Error: /api/module_list/1/
Traceback (most recent call last):
  File "E:\Python35\lib\site-packages\django\core\handlers\exception.py", line 35, in inner
    response = get_response(request)
  File "E:\Python35\lib\site-packages\django\core\handlers\base.py", line 128, in _get_response
    response = self.process_exception_by_middleware(e, request)
  File "E:\Python35\lib\site-packages\django\core\handlers\base.py", line 126, in _get_response
    response = wrapped_callback(request, *callback_args, **callback_kwargs)
  File "D:\HttpRunnerManager\HttpRunnerManager\activator.py", line 23, in process
    app = __import__("%s.views" % app)
  File "D:\HttpRunnerManager\ApiManager\views.py", line 13, in <module>
    from ApiManager.utils.pagination import get_pager_info
  File "D:\HttpRunnerManager\ApiManager\utils\pagination.py", line 96
    obj =
         ^
SyntaxError: invalid syntax
2018-04-25 11:18:30,827 [HttpRunnerManager:59] [operation:add_project_data] [INFO]- 项目更新成功：{'publish_app': 'feaw', 'responsible_name': 'fdfd', 'dev_user': 'fda', 'project_name': 'ceshi', 'simple_desc': 'fda', 'other_desc': 'fda', 'test_user': 'fddf'}
2018-04-25 11:23:36,772 [django.request:118] [exception:handle_uncaught_exception] [ERROR]- Internal Server Error: /api/add_case/
Traceback (most recent call last):
  File "D:\HttpRunnerManager\HttpRunnerManager\activator.py", line 29, in process
    result = fun(request, index)
TypeError: add_case() takes 1 positional argument but 2 were given

During handling of the above exception, another exception occurred:

Traceback (most recent call last):
  File "E:\Python35\lib\site-packages\django\db\models\sql\query.py", line 1683, in add_fields
    join_info = self.setup_joins(name.split(LOOKUP_SEP), opts, alias, allow_many=allow_m2m)
  File "E:\Python35\lib\site-packages\django\db\models\sql\query.py", line 1448, in setup_joins
    names, opts, allow_many, fail_on_missing=True)
  File "E:\Python35\lib\site-packages\django\db\models\sql\query.py", line 1379, in names_to_path
    "Choices are: %s" % (name, ", ".join(available)))
django.core.exceptions.FieldError: Cannot resolve keyword 'pro_name' into field. Choices are: create_time, dev_user, id, moduleinfo, other_desc, project_name, publish_app, responsible_name, simple_desc, test_user, update_time

During handling of the above exception, another exception occurred:

Traceback (most recent call last):
  File "E:\Python35\lib\site-packages\django\core\handlers\exception.py", line 35, in inner
    response = get_response(request)
  File "E:\Python35\lib\site-packages\django\core\handlers\base.py", line 128, in _get_response
    response = self.process_exception_by_middleware(e, request)
  File "E:\Python35\lib\site-packages\django\core\handlers\base.py", line 126, in _get_response
    response = wrapped_callback(request, *callback_args, **callback_kwargs)
  File "D:\HttpRunnerManager\HttpRunnerManager\activator.py", line 31, in process
    result = fun(request)
  File "D:\HttpRunnerManager\ApiManager\views.py", line 144, in add_case
    'project': ProjectInfo.objects.all().values('pro_name').order_by('-create_time')
  File "E:\Python35\lib\site-packages\django\db\models\query.py", line 742, in values
    clone = self._values(*fields, **expressions)
  File "E:\Python35\lib\site-packages\django\db\models\query.py", line 737, in _values
    clone.query.set_values(fields)
  File "E:\Python35\lib\site-packages\django\db\models\sql\query.py", line 1935, in set_values
    self.add_fields(field_names, True)
  File "E:\Python35\lib\site-packages\django\db\models\sql\query.py", line 1706, in add_fields
    "Choices are: %s" % (name, ", ".join(names)))
django.core.exceptions.FieldError: Cannot resolve keyword 'pro_name' into field. Choices are: create_time, dev_user, id, moduleinfo, other_desc, project_name, publish_app, responsible_name, simple_desc, test_user, update_time
2018-04-25 11:46:40,776 [django.request:118] [exception:handle_uncaught_exception] [ERROR]- Internal Server Error: /api/test_list/1/
Traceback (most recent call last):
  File "E:\Python35\lib\site-packages\django\core\handlers\exception.py", line 35, in inner
    response = get_response(request)
  File "E:\Python35\lib\site-packages\django\core\handlers\base.py", line 128, in _get_response
    response = self.process_exception_by_middleware(e, request)
  File "E:\Python35\lib\site-packages\django\core\handlers\base.py", line 126, in _get_response
    response = wrapped_callback(request, *callback_args, **callback_kwargs)
  File "D:\HttpRunnerManager\HttpRunnerManager\activator.py", line 29, in process
    result = fun(request, index)
  File "D:\HttpRunnerManager\ApiManager\views.py", line 301, in test_list
    TestCaseInfo, filter_query, '/api/test_list/', id)
  File "D:\HttpRunnerManager\ApiManager\utils\pagination.py", line 112, in get_pager_info
    obj = obj.filter(name__contains=name) if name is not '' else obj.filter(auth__contains=user)
  File "E:\Python35\lib\site-packages\django\db\models\query.py", line 836, in filter
    return self._filter_or_exclude(False, *args, **kwargs)
  File "E:\Python35\lib\site-packages\django\db\models\query.py", line 854, in _filter_or_exclude
    clone.query.add_q(Q(*args, **kwargs))
  File "E:\Python35\lib\site-packages\django\db\models\sql\query.py", line 1253, in add_q
    clause, _ = self._add_q(q_object, self.used_aliases)
  File "E:\Python35\lib\site-packages\django\db\models\sql\query.py", line 1277, in _add_q
    split_subq=split_subq,
  File "E:\Python35\lib\site-packages\django\db\models\sql\query.py", line 1153, in build_filter
    lookups, parts, reffed_expression = self.solve_lookup_type(arg)
  File "E:\Python35\lib\site-packages\django\db\models\sql\query.py", line 1015, in solve_lookup_type
    _, field, _, lookup_parts = self.names_to_path(lookup_splitted, self.get_meta())
  File "E:\Python35\lib\site-packages\django\db\models\sql\query.py", line 1379, in names_to_path
    "Choices are: %s" % (name, ", ".join(available)))
django.core.exceptions.FieldError: Cannot resolve keyword 'auth' into field. Choices are: author, belong_module, belong_module_id, belong_project, create_time, id, include, name, request, type, update_time
2018-04-25 12:18:45,549 [django.request:118] [exception:handle_uncaught_exception] [ERROR]- Internal Server Error: /api/add_config/
Traceback (most recent call last):
  File "D:\HttpRunnerManager\HttpRunnerManager\activator.py", line 29, in process
    result = fun(request, index)
TypeError: add_config() takes 1 positional argument but 2 were given

During handling of the above exception, another exception occurred:

Traceback (most recent call last):
  File "E:\Python35\lib\site-packages\django\db\models\sql\query.py", line 1683, in add_fields
    join_info = self.setup_joins(name.split(LOOKUP_SEP), opts, alias, allow_many=allow_m2m)
  File "E:\Python35\lib\site-packages\django\db\models\sql\query.py", line 1448, in setup_joins
    names, opts, allow_many, fail_on_missing=True)
  File "E:\Python35\lib\site-packages\django\db\models\sql\query.py", line 1379, in names_to_path
    "Choices are: %s" % (name, ", ".join(available)))
django.core.exceptions.FieldError: Cannot resolve keyword 'pro_name' into field. Choices are: create_time, dev_user, id, moduleinfo, other_desc, project_name, publish_app, responsible_name, simple_desc, test_user, update_time

During handling of the above exception, another exception occurred:

Traceback (most recent call last):
  File "E:\Python35\lib\site-packages\django\core\handlers\exception.py", line 35, in inner
    response = get_response(request)
  File "E:\Python35\lib\site-packages\django\core\handlers\base.py", line 128, in _get_response
    response = self.process_exception_by_middleware(e, request)
  File "E:\Python35\lib\site-packages\django\core\handlers\base.py", line 126, in _get_response
    response = wrapped_callback(request, *callback_args, **callback_kwargs)
  File "D:\HttpRunnerManager\HttpRunnerManager\activator.py", line 31, in process
    result = fun(request)
  File "D:\HttpRunnerManager\ApiManager\views.py", line 164, in add_config
    'project': ProjectInfo.objects.all().values('pro_name').order_by('-create_time')
  File "E:\Python35\lib\site-packages\django\db\models\query.py", line 742, in values
    clone = self._values(*fields, **expressions)
  File "E:\Python35\lib\site-packages\django\db\models\query.py", line 737, in _values
    clone.query.set_values(fields)
  File "E:\Python35\lib\site-packages\django\db\models\sql\query.py", line 1935, in set_values
    self.add_fields(field_names, True)
  File "E:\Python35\lib\site-packages\django\db\models\sql\query.py", line 1706, in add_fields
    "Choices are: %s" % (name, ", ".join(names)))
django.core.exceptions.FieldError: Cannot resolve keyword 'pro_name' into field. Choices are: create_time, dev_user, id, moduleinfo, other_desc, project_name, publish_app, responsible_name, simple_desc, test_user, update_time
2018-04-26 09:31:40,128 [HttpRunnerManager:29] [views:login] [INFO]- yinquanwang 登录成功
2018-04-26 09:33:23,950 [django.request:118] [exception:handle_uncaught_exception] [ERROR]- Internal Server Error: /api/add_config/
Traceback (most recent call last):
  File "D:\HttpRunnerManager\HttpRunnerManager\activator.py", line 29, in process
    result = fun(request, index)
TypeError: add_config() takes 1 positional argument but 2 were given

During handling of the above exception, another exception occurred:

Traceback (most recent call last):
  File "E:\Python35\lib\site-packages\django\db\models\sql\query.py", line 1683, in add_fields
    join_info = self.setup_joins(name.split(LOOKUP_SEP), opts, alias, allow_many=allow_m2m)
  File "E:\Python35\lib\site-packages\django\db\models\sql\query.py", line 1448, in setup_joins
    names, opts, allow_many, fail_on_missing=True)
  File "E:\Python35\lib\site-packages\django\db\models\sql\query.py", line 1379, in names_to_path
    "Choices are: %s" % (name, ", ".join(available)))
django.core.exceptions.FieldError: Cannot resolve keyword 'pro_name' into field. Choices are: create_time, dev_user, id, moduleinfo, other_desc, project_name, publish_app, responsible_name, simple_desc, test_user, update_time

During handling of the above exception, another exception occurred:

Traceback (most recent call last):
  File "E:\Python35\lib\site-packages\django\core\handlers\exception.py", line 35, in inner
    response = get_response(request)
  File "E:\Python35\lib\site-packages\django\core\handlers\base.py", line 128, in _get_response
    response = self.process_exception_by_middleware(e, request)
  File "E:\Python35\lib\site-packages\django\core\handlers\base.py", line 126, in _get_response
    response = wrapped_callback(request, *callback_args, **callback_kwargs)
  File "D:\HttpRunnerManager\HttpRunnerManager\activator.py", line 31, in process
    result = fun(request)
  File "D:\HttpRunnerManager\ApiManager\views.py", line 164, in add_config
    'project': ProjectInfo.objects.all().values('pro_name').order_by('-create_time')
  File "E:\Python35\lib\site-packages\django\db\models\query.py", line 742, in values
    clone = self._values(*fields, **expressions)
  File "E:\Python35\lib\site-packages\django\db\models\query.py", line 737, in _values
    clone.query.set_values(fields)
  File "E:\Python35\lib\site-packages\django\db\models\sql\query.py", line 1935, in set_values
    self.add_fields(field_names, True)
  File "E:\Python35\lib\site-packages\django\db\models\sql\query.py", line 1706, in add_fields
    "Choices are: %s" % (name, ", ".join(names)))
django.core.exceptions.FieldError: Cannot resolve keyword 'pro_name' into field. Choices are: create_time, dev_user, id, moduleinfo, other_desc, project_name, publish_app, responsible_name, simple_desc, test_user, update_time
2018-04-26 09:39:18,397 [HttpRunnerManager:179] [operation:change_status] [INFO]- 6状态已更改！
2018-04-26 09:40:19,261 [django.request:118] [exception:handle_uncaught_exception] [ERROR]- Internal Server Error: /api/add_case/
Traceback (most recent call last):
  File "D:\HttpRunnerManager\HttpRunnerManager\activator.py", line 29, in process
    result = fun(request, index)
TypeError: add_case() takes 1 positional argument but 2 were given

During handling of the above exception, another exception occurred:

Traceback (most recent call last):
  File "E:\Python35\lib\site-packages\django\db\models\sql\query.py", line 1683, in add_fields
    join_info = self.setup_joins(name.split(LOOKUP_SEP), opts, alias, allow_many=allow_m2m)
  File "E:\Python35\lib\site-packages\django\db\models\sql\query.py", line 1448, in setup_joins
    names, opts, allow_many, fail_on_missing=True)
  File "E:\Python35\lib\site-packages\django\db\models\sql\query.py", line 1379, in names_to_path
    "Choices are: %s" % (name, ", ".join(available)))
django.core.exceptions.FieldError: Cannot resolve keyword 'pro_name' into field. Choices are: create_time, dev_user, id, moduleinfo, other_desc, project_name, publish_app, responsible_name, simple_desc, test_user, update_time

During handling of the above exception, another exception occurred:

Traceback (most recent call last):
  File "E:\Python35\lib\site-packages\django\core\handlers\exception.py", line 35, in inner
    response = get_response(request)
  File "E:\Python35\lib\site-packages\django\core\handlers\base.py", line 128, in _get_response
    response = self.process_exception_by_middleware(e, request)
  File "E:\Python35\lib\site-packages\django\core\handlers\base.py", line 126, in _get_response
    response = wrapped_callback(request, *callback_args, **callback_kwargs)
  File "D:\HttpRunnerManager\HttpRunnerManager\activator.py", line 31, in process
    result = fun(request)
  File "D:\HttpRunnerManager\ApiManager\views.py", line 144, in add_case
    'project': ProjectInfo.objects.all().values('pro_name').order_by('-create_time')
  File "E:\Python35\lib\site-packages\django\db\models\query.py", line 742, in values
    clone = self._values(*fields, **expressions)
  File "E:\Python35\lib\site-packages\django\db\models\query.py", line 737, in _values
    clone.query.set_values(fields)
  File "E:\Python35\lib\site-packages\django\db\models\sql\query.py", line 1935, in set_values
    self.add_fields(field_names, True)
  File "E:\Python35\lib\site-packages\django\db\models\sql\query.py", line 1706, in add_fields
    "Choices are: %s" % (name, ", ".join(names)))
django.core.exceptions.FieldError: Cannot resolve keyword 'pro_name' into field. Choices are: create_time, dev_user, id, moduleinfo, other_desc, project_name, publish_app, responsible_name, simple_desc, test_user, update_time
2018-04-26 10:29:36,178 [django.request:118] [exception:handle_uncaught_exception] [ERROR]- Internal Server Error: /api/env_set/
Traceback (most recent call last):
  File "E:\Python35\lib\site-packages\django\core\handlers\exception.py", line 35, in inner
    response = get_response(request)
  File "E:\Python35\lib\site-packages\django\core\handlers\base.py", line 128, in _get_response
    response = self.process_exception_by_middleware(e, request)
  File "E:\Python35\lib\site-packages\django\core\handlers\base.py", line 126, in _get_response
    response = wrapped_callback(request, *callback_args, **callback_kwargs)
  File "D:\HttpRunnerManager\HttpRunnerManager\activator.py", line 23, in process
    app = __import__("%s.views" % app)
  File "D:\HttpRunnerManager\ApiManager\views.py", line 10, in <module>
    from ApiManager.utils.common import module_info_logic, project_info_logic, case_info_logic, config_info_logic, \
  File "D:\HttpRunnerManager\ApiManager\utils\common.py", line 6, in <module>
    from ApiManager.utils.operation import add_project_data, add_module_data, add_case_data, add_config_data, \
  File "D:\HttpRunnerManager\ApiManager\utils\operation.py", line 175
    '''改变状态'''
             ^
IndentationError: expected an indented block
2018-04-26 11:17:41,205 [HttpRunnerManager:27] [views:login] [INFO]- yinquanwang 登录成功
2018-04-26 11:19:36,060 [django.request:118] [exception:handle_uncaught_exception] [ERROR]- Internal Server Error: /api/env_set/
Traceback (most recent call last):
  File "D:\HttpRunnerManager\HttpRunnerManager\activator.py", line 29, in process
    result = fun(request, index)
TypeError: env_set() takes 1 positional argument but 2 were given

During handling of the above exception, another exception occurred:

Traceback (most recent call last):
  File "E:\Python35\lib\site-packages\django\core\handlers\exception.py", line 35, in inner
    response = get_response(request)
  File "E:\Python35\lib\site-packages\django\core\handlers\base.py", line 128, in _get_response
    response = self.process_exception_by_middleware(e, request)
  File "E:\Python35\lib\site-packages\django\core\handlers\base.py", line 126, in _get_response
    response = wrapped_callback(request, *callback_args, **callback_kwargs)
  File "D:\HttpRunnerManager\HttpRunnerManager\activator.py", line 31, in process
    result = fun(request)
  File "D:\HttpRunnerManager\ApiManager\views.py", line 400, in env_set
    msg = add_env_data({'env_name': env_name, 'base_url': base_url, 'simple_desc': simple_desc})
TypeError: add_env_data() takes 0 positional arguments but 1 was given
2018-04-26 11:19:48,364 [django.request:118] [exception:handle_uncaught_exception] [ERROR]- Internal Server Error: /api/env_set/
Traceback (most recent call last):
  File "D:\HttpRunnerManager\HttpRunnerManager\activator.py", line 29, in process
    result = fun(request, index)
TypeError: env_set() takes 1 positional argument but 2 were given

During handling of the above exception, another exception occurred:

Traceback (most recent call last):
  File "E:\Python35\lib\site-packages\django\core\handlers\exception.py", line 35, in inner
    response = get_response(request)
  File "E:\Python35\lib\site-packages\django\core\handlers\base.py", line 128, in _get_response
    response = self.process_exception_by_middleware(e, request)
  File "E:\Python35\lib\site-packages\django\core\handlers\base.py", line 126, in _get_response
    response = wrapped_callback(request, *callback_args, **callback_kwargs)
  File "D:\HttpRunnerManager\HttpRunnerManager\activator.py", line 31, in process
    result = fun(request)
  File "D:\HttpRunnerManager\ApiManager\views.py", line 400, in env_set
    msg = add_env_data({'env_name': env_name, 'base_url': base_url, 'simple_desc': simple_desc})
TypeError: add_env_data() takes 0 positional arguments but 1 was given
2018-04-26 11:20:09,447 [django.request:118] [exception:handle_uncaught_exception] [ERROR]- Internal Server Error: /api/env_set/
Traceback (most recent call last):
  File "D:\HttpRunnerManager\HttpRunnerManager\activator.py", line 29, in process
    result = fun(request, index)
TypeError: env_set() takes 1 positional argument but 2 were given

During handling of the above exception, another exception occurred:

Traceback (most recent call last):
  File "E:\Python35\lib\site-packages\django\core\handlers\exception.py", line 35, in inner
    response = get_response(request)
  File "E:\Python35\lib\site-packages\django\core\handlers\base.py", line 128, in _get_response
    response = self.process_exception_by_middleware(e, request)
  File "E:\Python35\lib\site-packages\django\core\handlers\base.py", line 126, in _get_response
    response = wrapped_callback(request, *callback_args, **callback_kwargs)
  File "D:\HttpRunnerManager\HttpRunnerManager\activator.py", line 31, in process
    result = fun(request)
  File "D:\HttpRunnerManager\ApiManager\views.py", line 400, in env_set
    msg = add_env_data({'env_name': env_name, 'base_url': base_url, 'simple_desc': simple_desc})
TypeError: add_env_data() takes 0 positional arguments but 1 was given
2018-04-26 11:42:35,074 [HttpRunnerManager:56] [views:log_out] [INFO]- yinquanwang退出
2018-04-26 11:42:36,458 [HttpRunnerManager:27] [views:login] [INFO]- yinquanwang 登录成功
2018-04-26 11:43:52,849 [HttpRunnerManager:56] [views:log_out] [INFO]- yinquanwang退出
2018-04-26 11:43:54,364 [HttpRunnerManager:27] [views:login] [INFO]- yinquanwang 登录成功
2018-04-26 11:44:52,229 [django.request:118] [exception:handle_uncaught_exception] [ERROR]- Internal Server Error: /api/env_list/1/
Traceback (most recent call last):
  File "D:\HttpRunnerManager\HttpRunnerManager\activator.py", line 29, in process
    result = fun(request, index)
  File "D:\HttpRunnerManager\ApiManager\views.py", line 416, in env_list
    EnvInfo, None, '/api/env_list/', id)
  File "D:\HttpRunnerManager\ApiManager\utils\pagination.py", line 85, in get_pager_info
    id = int(id)
TypeError: int() argument must be a string, a bytes-like object or a number, not 'NoneType'

During handling of the above exception, another exception occurred:

Traceback (most recent call last):
  File "E:\Python35\lib\site-packages\django\core\handlers\exception.py", line 35, in inner
    response = get_response(request)
  File "E:\Python35\lib\site-packages\django\core\handlers\base.py", line 128, in _get_response
    response = self.process_exception_by_middleware(e, request)
  File "E:\Python35\lib\site-packages\django\core\handlers\base.py", line 126, in _get_response
    response = wrapped_callback(request, *callback_args, **callback_kwargs)
  File "D:\HttpRunnerManager\HttpRunnerManager\activator.py", line 31, in process
    result = fun(request)
TypeError: env_list() missing 1 required positional argument: 'id'
2018-04-26 11:48:10,257 [django.request:118] [exception:handle_uncaught_exception] [ERROR]- Internal Server Error: /api/env_list/1/
Traceback (most recent call last):
  File "E:\Python35\lib\site-packages\django\core\handlers\exception.py", line 35, in inner
    response = get_response(request)
  File "E:\Python35\lib\site-packages\django\core\handlers\base.py", line 128, in _get_response
    response = self.process_exception_by_middleware(e, request)
  File "E:\Python35\lib\site-packages\django\core\handlers\base.py", line 126, in _get_response
    response = wrapped_callback(request, *callback_args, **callback_kwargs)
  File "D:\HttpRunnerManager\HttpRunnerManager\activator.py", line 29, in process
    result = fun(request, index)
  File "D:\HttpRunnerManager\ApiManager\views.py", line 415, in env_list
    EnvInfo, None, '/api/env_list/', id)
  File "D:\HttpRunnerManager\ApiManager\utils\pagination.py", line 103, in get_pager_info
    obj = obj.filter(type__exact=1) if url == '/api/test_list/' else obj.filter(type__exact=2)
  File "E:\Python35\lib\site-packages\django\db\models\manager.py", line 82, in manager_method
    return getattr(self.get_queryset(), name)(*args, **kwargs)
  File "E:\Python35\lib\site-packages\django\db\models\query.py", line 836, in filter
    return self._filter_or_exclude(False, *args, **kwargs)
  File "E:\Python35\lib\site-packages\django\db\models\query.py", line 854, in _filter_or_exclude
    clone.query.add_q(Q(*args, **kwargs))
  File "E:\Python35\lib\site-packages\django\db\models\sql\query.py", line 1253, in add_q
    clause, _ = self._add_q(q_object, self.used_aliases)
  File "E:\Python35\lib\site-packages\django\db\models\sql\query.py", line 1277, in _add_q
    split_subq=split_subq,
  File "E:\Python35\lib\site-packages\django\db\models\sql\query.py", line 1153, in build_filter
    lookups, parts, reffed_expression = self.solve_lookup_type(arg)
  File "E:\Python35\lib\site-packages\django\db\models\sql\query.py", line 1015, in solve_lookup_type
    _, field, _, lookup_parts = self.names_to_path(lookup_splitted, self.get_meta())
  File "E:\Python35\lib\site-packages\django\db\models\sql\query.py", line 1379, in names_to_path
    "Choices are: %s" % (name, ", ".join(available)))
django.core.exceptions.FieldError: Cannot resolve keyword 'type' into field. Choices are: base_url, create_time, env_name, id, simple_desc, update_time
2018-04-26 12:21:20,528 [django.request:118] [exception:handle_uncaught_exception] [ERROR]- Internal Server Error: /api/add_config/
Traceback (most recent call last):
  File "D:\HttpRunnerManager\HttpRunnerManager\activator.py", line 29, in process
    result = fun(request, index)
TypeError: add_config() takes 1 positional argument but 2 were given

During handling of the above exception, another exception occurred:

Traceback (most recent call last):
  File "E:\Python35\lib\site-packages\django\db\models\sql\query.py", line 1683, in add_fields
    join_info = self.setup_joins(name.split(LOOKUP_SEP), opts, alias, allow_many=allow_m2m)
  File "E:\Python35\lib\site-packages\django\db\models\sql\query.py", line 1448, in setup_joins
    names, opts, allow_many, fail_on_missing=True)
  File "E:\Python35\lib\site-packages\django\db\models\sql\query.py", line 1379, in names_to_path
    "Choices are: %s" % (name, ", ".join(available)))
django.core.exceptions.FieldError: Cannot resolve keyword 'pro_name' into field. Choices are: create_time, dev_user, id, moduleinfo, other_desc, project_name, publish_app, responsible_name, simple_desc, test_user, update_time

During handling of the above exception, another exception occurred:

Traceback (most recent call last):
  File "E:\Python35\lib\site-packages\django\core\handlers\exception.py", line 35, in inner
    response = get_response(request)
  File "E:\Python35\lib\site-packages\django\core\handlers\base.py", line 128, in _get_response
    response = self.process_exception_by_middleware(e, request)
  File "E:\Python35\lib\site-packages\django\core\handlers\base.py", line 126, in _get_response
    response = wrapped_callback(request, *callback_args, **callback_kwargs)
  File "D:\HttpRunnerManager\HttpRunnerManager\activator.py", line 31, in process
    result = fun(request)
  File "D:\HttpRunnerManager\ApiManager\views.py", line 164, in add_config
    'project': ProjectInfo.objects.all().values('pro_name').order_by('-create_time')
  File "E:\Python35\lib\site-packages\django\db\models\query.py", line 742, in values
    clone = self._values(*fields, **expressions)
  File "E:\Python35\lib\site-packages\django\db\models\query.py", line 737, in _values
    clone.query.set_values(fields)
  File "E:\Python35\lib\site-packages\django\db\models\sql\query.py", line 1935, in set_values
    self.add_fields(field_names, True)
  File "E:\Python35\lib\site-packages\django\db\models\sql\query.py", line 1706, in add_fields
    "Choices are: %s" % (name, ", ".join(names)))
django.core.exceptions.FieldError: Cannot resolve keyword 'pro_name' into field. Choices are: create_time, dev_user, id, moduleinfo, other_desc, project_name, publish_app, responsible_name, simple_desc, test_user, update_time
2018-04-26 12:21:55,083 [django.request:118] [exception:handle_uncaught_exception] [ERROR]- Internal Server Error: /api/add_config/
Traceback (most recent call last):
  File "D:\HttpRunnerManager\HttpRunnerManager\activator.py", line 29, in process
    result = fun(request, index)
TypeError: add_config() takes 1 positional argument but 2 were given

During handling of the above exception, another exception occurred:

Traceback (most recent call last):
  File "E:\Python35\lib\site-packages\django\db\models\sql\query.py", line 1683, in add_fields
    join_info = self.setup_joins(name.split(LOOKUP_SEP), opts, alias, allow_many=allow_m2m)
  File "E:\Python35\lib\site-packages\django\db\models\sql\query.py", line 1448, in setup_joins
    names, opts, allow_many, fail_on_missing=True)
  File "E:\Python35\lib\site-packages\django\db\models\sql\query.py", line 1379, in names_to_path
    "Choices are: %s" % (name, ", ".join(available)))
django.core.exceptions.FieldError: Cannot resolve keyword 'pro_name' into field. Choices are: create_time, dev_user, id, moduleinfo, other_desc, project_name, publish_app, responsible_name, simple_desc, test_user, update_time

During handling of the above exception, another exception occurred:

Traceback (most recent call last):
  File "E:\Python35\lib\site-packages\django\core\handlers\exception.py", line 35, in inner
    response = get_response(request)
  File "E:\Python35\lib\site-packages\django\core\handlers\base.py", line 128, in _get_response
    response = self.process_exception_by_middleware(e, request)
  File "E:\Python35\lib\site-packages\django\core\handlers\base.py", line 126, in _get_response
    response = wrapped_callback(request, *callback_args, **callback_kwargs)
  File "D:\HttpRunnerManager\HttpRunnerManager\activator.py", line 31, in process
    result = fun(request)
  File "D:\HttpRunnerManager\ApiManager\views.py", line 164, in add_config
    'project': ProjectInfo.objects.all().values('pro_name').order_by('-create_time')
  File "E:\Python35\lib\site-packages\django\db\models\query.py", line 742, in values
    clone = self._values(*fields, **expressions)
  File "E:\Python35\lib\site-packages\django\db\models\query.py", line 737, in _values
    clone.query.set_values(fields)
  File "E:\Python35\lib\site-packages\django\db\models\sql\query.py", line 1935, in set_values
    self.add_fields(field_names, True)
  File "E:\Python35\lib\site-packages\django\db\models\sql\query.py", line 1706, in add_fields
    "Choices are: %s" % (name, ", ".join(names)))
django.core.exceptions.FieldError: Cannot resolve keyword 'pro_name' into field. Choices are: create_time, dev_user, id, moduleinfo, other_desc, project_name, publish_app, responsible_name, simple_desc, test_user, update_time
2018-04-26 13:43:30,273 [HttpRunnerManager:56] [views:log_out] [INFO]- yinquanwang退出
2018-04-26 13:43:51,127 [HttpRunnerManager:27] [views:login] [INFO]- yinquanwang 登录成功
2018-04-26 14:09:44,004 [django.request:118] [exception:handle_uncaught_exception] [ERROR]- Internal Server Error: /api/env_list/1/
Traceback (most recent call last):
  File "E:\Python35\lib\site-packages\django\core\handlers\exception.py", line 35, in inner
    response = get_response(request)
  File "E:\Python35\lib\site-packages\django\core\handlers\base.py", line 128, in _get_response
    response = self.process_exception_by_middleware(e, request)
  File "E:\Python35\lib\site-packages\django\core\handlers\base.py", line 126, in _get_response
    response = wrapped_callback(request, *callback_args, **callback_kwargs)
  File "D:\HttpRunnerManager\HttpRunnerManager\activator.py", line 23, in process
    app = __import__("%s.views" % app)
  File "D:\HttpRunnerManager\ApiManager\views.py", line 406
    else
        ^
SyntaxError: invalid syntax
2018-04-26 14:29:13,912 [django.request:118] [exception:handle_uncaught_exception] [ERROR]- Internal Server Error: /api/env_set/
Traceback (most recent call last):
  File "D:\HttpRunnerManager\HttpRunnerManager\activator.py", line 29, in process
    result = fun(request, index)
TypeError: env_set() takes 1 positional argument but 2 were given

During handling of the above exception, another exception occurred:

Traceback (most recent call last):
  File "E:\Python35\lib\site-packages\django\core\handlers\exception.py", line 35, in inner
    response = get_response(request)
  File "E:\Python35\lib\site-packages\django\core\handlers\base.py", line 128, in _get_response
    response = self.process_exception_by_middleware(e, request)
  File "E:\Python35\lib\site-packages\django\core\handlers\base.py", line 126, in _get_response
    response = wrapped_callback(request, *callback_args, **callback_kwargs)
  File "D:\HttpRunnerManager\HttpRunnerManager\activator.py", line 31, in process
    result = fun(request)
  File "D:\HttpRunnerManager\ApiManager\views.py", line 405, in env_set
    msg = add_env_data(mode, **env_lists)
TypeError: add_env_data() takes 0 positional arguments but 1 was given
2018-04-26 14:30:06,769 [django.request:118] [exception:handle_uncaught_exception] [ERROR]- Internal Server Error: /api/env_set/
Traceback (most recent call last):
  File "D:\HttpRunnerManager\HttpRunnerManager\activator.py", line 29, in process
    result = fun(request, index)
TypeError: env_set() takes 1 positional argument but 2 were given

During handling of the above exception, another exception occurred:

Traceback (most recent call last):
  File "E:\Python35\lib\site-packages\django\core\handlers\exception.py", line 35, in inner
    response = get_response(request)
  File "E:\Python35\lib\site-packages\django\core\handlers\base.py", line 128, in _get_response
    response = self.process_exception_by_middleware(e, request)
  File "E:\Python35\lib\site-packages\django\core\handlers\base.py", line 126, in _get_response
    response = wrapped_callback(request, *callback_args, **callback_kwargs)
  File "D:\HttpRunnerManager\HttpRunnerManager\activator.py", line 31, in process
    result = fun(request)
  File "D:\HttpRunnerManager\ApiManager\views.py", line 405, in env_set
    msg = add_env_data(**env_lists)
  File "D:\HttpRunnerManager\ApiManager\utils\operation.py", line 191, in add_env_data
    EnvInfo.objects.update(index, **kwargs)
  File "E:\Python35\lib\site-packages\django\db\models\manager.py", line 82, in manager_method
    return getattr(self.get_queryset(), name)(*args, **kwargs)
TypeError: update() takes 1 positional argument but 2 were given
2018-04-26 14:30:26,943 [django.request:118] [exception:handle_uncaught_exception] [ERROR]- Internal Server Error: /api/env_set/
Traceback (most recent call last):
  File "D:\HttpRunnerManager\HttpRunnerManager\activator.py", line 29, in process
    result = fun(request, index)
TypeError: env_set() takes 1 positional argument but 2 were given

During handling of the above exception, another exception occurred:

Traceback (most recent call last):
  File "E:\Python35\lib\site-packages\django\core\handlers\exception.py", line 35, in inner
    response = get_response(request)
  File "E:\Python35\lib\site-packages\django\core\handlers\base.py", line 128, in _get_response
    response = self.process_exception_by_middleware(e, request)
  File "E:\Python35\lib\site-packages\django\core\handlers\base.py", line 126, in _get_response
    response = wrapped_callback(request, *callback_args, **callback_kwargs)
  File "D:\HttpRunnerManager\HttpRunnerManager\activator.py", line 31, in process
    result = fun(request)
  File "D:\HttpRunnerManager\ApiManager\views.py", line 405, in env_set
    msg = add_env_data(**env_lists)
  File "D:\HttpRunnerManager\ApiManager\utils\operation.py", line 191, in add_env_data
    EnvInfo.objects.update(index, **kwargs)
  File "E:\Python35\lib\site-packages\django\db\models\manager.py", line 82, in manager_method
    return getattr(self.get_queryset(), name)(*args, **kwargs)
TypeError: update() takes 1 positional argument but 2 were given
2018-04-26 14:30:51,162 [django.request:118] [exception:handle_uncaught_exception] [ERROR]- Internal Server Error: /api/env_set/
Traceback (most recent call last):
  File "D:\HttpRunnerManager\HttpRunnerManager\activator.py", line 29, in process
    result = fun(request, index)
TypeError: env_set() takes 1 positional argument but 2 were given

During handling of the above exception, another exception occurred:

Traceback (most recent call last):
  File "E:\Python35\lib\site-packages\django\core\handlers\exception.py", line 35, in inner
    response = get_response(request)
  File "E:\Python35\lib\site-packages\django\core\handlers\base.py", line 128, in _get_response
    response = self.process_exception_by_middleware(e, request)
  File "E:\Python35\lib\site-packages\django\core\handlers\base.py", line 126, in _get_response
    response = wrapped_callback(request, *callback_args, **callback_kwargs)
  File "D:\HttpRunnerManager\HttpRunnerManager\activator.py", line 31, in process
    result = fun(request)
  File "D:\HttpRunnerManager\ApiManager\views.py", line 405, in env_set
    msg = add_env_data(**env_lists)
  File "D:\HttpRunnerManager\ApiManager\utils\operation.py", line 191, in add_env_data
    EnvInfo.objects.update(index, **kwargs)
  File "E:\Python35\lib\site-packages\django\db\models\manager.py", line 82, in manager_method
    return getattr(self.get_queryset(), name)(*args, **kwargs)
TypeError: update() takes 1 positional argument but 2 were given
2018-04-26 14:38:11,525 [HttpRunnerManager:102] [operation:add_module_data] [INFO]- 模块更新成功：{'other_desc': '', 'simple_desc': '', 'test_user': '发', 'module_name': '发发 的'}
2018-04-26 14:46:26,550 [django.request:118] [exception:handle_uncaught_exception] [ERROR]- Internal Server Error: /api/env_list/1/
Traceback (most recent call last):
  File "E:\Python35\lib\site-packages\django\core\handlers\exception.py", line 35, in inner
    response = get_response(request)
  File "E:\Python35\lib\site-packages\django\core\handlers\base.py", line 139, in _get_response
    "returned None instead." % (callback.__module__, view_name)
ValueError: The view HttpRunnerManager.activator.process didn't return an HttpResponse object. It returned None instead.
2018-04-26 14:53:24,728 [django.request:118] [exception:handle_uncaught_exception] [ERROR]- Internal Server Error: /api/env_list/1/
Traceback (most recent call last):
  File "E:\Python35\lib\site-packages\django\core\handlers\exception.py", line 35, in inner
    response = get_response(request)
  File "E:\Python35\lib\site-packages\django\core\handlers\base.py", line 139, in _get_response
    "returned None instead." % (callback.__module__, view_name)
ValueError: The view HttpRunnerManager.activator.process didn't return an HttpResponse object. It returned None instead.
2018-04-26 14:58:19,671 [django.request:118] [exception:handle_uncaught_exception] [ERROR]- Internal Server Error: /api/env_set/
Traceback (most recent call last):
  File "D:\HttpRunnerManager\HttpRunnerManager\activator.py", line 29, in process
    result = fun(request, index)
TypeError: env_set() takes 1 positional argument but 2 were given

During handling of the above exception, another exception occurred:

Traceback (most recent call last):
  File "E:\Python35\lib\site-packages\django\core\handlers\exception.py", line 35, in inner
    response = get_response(request)
  File "E:\Python35\lib\site-packages\django\core\handlers\base.py", line 128, in _get_response
    response = self.process_exception_by_middleware(e, request)
  File "E:\Python35\lib\site-packages\django\core\handlers\base.py", line 126, in _get_response
    response = wrapped_callback(request, *callback_args, **callback_kwargs)
  File "D:\HttpRunnerManager\HttpRunnerManager\activator.py", line 31, in process
    result = fun(request)
  File "D:\HttpRunnerManager\ApiManager\views.py", line 404, in env_set
    msg = add_env_data(**env_lists)
  File "D:\HttpRunnerManager\ApiManager\utils\operation.py", line 189, in add_env_data
    if EnvInfo.objects.get_env_name(index) != env_name and EnvInfo.objects.filter(
  File "D:\HttpRunnerManager\ApiManager\managers.py", line 153, in get_env_name
    return self.get(id=int(index)).env_name
TypeError: int() argument must be a string, a bytes-like object or a number, not 'NoneType'
2018-04-26 14:59:25,392 [django.request:118] [exception:handle_uncaught_exception] [ERROR]- Internal Server Error: /api/env_set/
Traceback (most recent call last):
  File "D:\HttpRunnerManager\HttpRunnerManager\activator.py", line 29, in process
    result = fun(request, index)
TypeError: env_set() takes 1 positional argument but 2 were given

During handling of the above exception, another exception occurred:

Traceback (most recent call last):
  File "E:\Python35\lib\site-packages\django\core\handlers\exception.py", line 35, in inner
    response = get_response(request)
  File "E:\Python35\lib\site-packages\django\core\handlers\base.py", line 128, in _get_response
    response = self.process_exception_by_middleware(e, request)
  File "E:\Python35\lib\site-packages\django\core\handlers\base.py", line 126, in _get_response
    response = wrapped_callback(request, *callback_args, **callback_kwargs)
  File "D:\HttpRunnerManager\HttpRunnerManager\activator.py", line 31, in process
    result = fun(request)
  File "D:\HttpRunnerManager\ApiManager\views.py", line 404, in env_set
    msg = add_env_data(**env_lists)
  File "D:\HttpRunnerManager\ApiManager\utils\operation.py", line 189, in add_env_data
    if EnvInfo.objects.get_env_name(index) != env_name and EnvInfo.objects.filter(
  File "D:\HttpRunnerManager\ApiManager\managers.py", line 153, in get_env_name
    return self.get(id=int(index)).env_name
TypeError: int() argument must be a string, a bytes-like object or a number, not 'NoneType'
2018-04-26 15:00:27,137 [HttpRunnerManager:26] [views:login] [INFO]- yinquanwang 登录成功
2018-04-26 15:00:34,821 [django.request:118] [exception:handle_uncaught_exception] [ERROR]- Internal Server Error: /api/env_set/
Traceback (most recent call last):
  File "D:\HttpRunnerManager\HttpRunnerManager\activator.py", line 29, in process
    result = fun(request, index)
TypeError: env_set() takes 1 positional argument but 2 were given

During handling of the above exception, another exception occurred:

Traceback (most recent call last):
  File "E:\Python35\lib\site-packages\django\core\handlers\exception.py", line 35, in inner
    response = get_response(request)
  File "E:\Python35\lib\site-packages\django\core\handlers\base.py", line 128, in _get_response
    response = self.process_exception_by_middleware(e, request)
  File "E:\Python35\lib\site-packages\django\core\handlers\base.py", line 126, in _get_response
    response = wrapped_callback(request, *callback_args, **callback_kwargs)
  File "D:\HttpRunnerManager\HttpRunnerManager\activator.py", line 31, in process
    result = fun(request)
  File "D:\HttpRunnerManager\ApiManager\views.py", line 404, in env_set
    msg = add_env_data(**env_lists)
  File "D:\HttpRunnerManager\ApiManager\utils\operation.py", line 189, in add_env_data
    if EnvInfo.objects.get_env_name(index) != env_name and EnvInfo.objects.filter(
  File "D:\HttpRunnerManager\ApiManager\managers.py", line 153, in get_env_name
    return self.get(id=int(index)).env_name
TypeError: int() argument must be a string, a bytes-like object or a number, not 'NoneType'
2018-04-26 15:01:08,734 [django.request:118] [exception:handle_uncaught_exception] [ERROR]- Internal Server Error: /api/env_set/
Traceback (most recent call last):
  File "D:/HttpRunnerManager\HttpRunnerManager\activator.py", line 29, in process
    result = fun(request, index)
TypeError: env_set() takes 1 positional argument but 2 were given

During handling of the above exception, another exception occurred:

Traceback (most recent call last):
  File "E:\Python35\lib\site-packages\django\core\handlers\exception.py", line 35, in inner
    response = get_response(request)
  File "E:\Python35\lib\site-packages\django\core\handlers\base.py", line 128, in _get_response
    response = self.process_exception_by_middleware(e, request)
  File "E:\Python35\lib\site-packages\django\core\handlers\base.py", line 126, in _get_response
    response = wrapped_callback(request, *callback_args, **callback_kwargs)
  File "D:/HttpRunnerManager\HttpRunnerManager\activator.py", line 31, in process
    result = fun(request)
  File "D:/HttpRunnerManager\ApiManager\views.py", line 404, in env_set
    msg = add_env_data(**env_lists)
  File "D:/HttpRunnerManager\ApiManager\utils\operation.py", line 189, in add_env_data
    if EnvInfo.objects.get_env_name(index) != env_name and EnvInfo.objects.filter(
  File "D:/HttpRunnerManager\ApiManager\managers.py", line 153, in get_env_name
    return self.get(id=int(index)).env_name
TypeError: int() argument must be a string, a bytes-like object or a number, not 'NoneType'
2018-04-26 15:04:49,233 [django.request:118] [exception:handle_uncaught_exception] [ERROR]- Internal Server Error: /api/env_set/
Traceback (most recent call last):
  File "E:\Python35\lib\site-packages\django\core\handlers\exception.py", line 35, in inner
    response = get_response(request)
  File "E:\Python35\lib\site-packages\django\utils\deprecation.py", line 97, in __call__
    response = self.process_response(request, response)
  File "E:\Python35\lib\site-packages\django\middleware\clickjacking.py", line 26, in process_response
    if response.get('X-Frame-Options') is not None:
AttributeError: 'str' object has no attribute 'get'
2018-04-26 15:06:43,648 [django.request:118] [exception:handle_uncaught_exception] [ERROR]- Internal Server Error: /api/env_set/
Traceback (most recent call last):
  File "D:/HttpRunnerManager\HttpRunnerManager\activator.py", line 29, in process
    result = fun(request, index)
TypeError: env_set() takes 1 positional argument but 2 were given

During handling of the above exception, another exception occurred:

Traceback (most recent call last):
  File "E:\Python35\lib\site-packages\django\core\handlers\exception.py", line 35, in inner
    response = get_response(request)
  File "E:\Python35\lib\site-packages\django\core\handlers\base.py", line 128, in _get_response
    response = self.process_exception_by_middleware(e, request)
  File "E:\Python35\lib\site-packages\django\core\handlers\base.py", line 126, in _get_response
    response = wrapped_callback(request, *callback_args, **callback_kwargs)
  File "D:/HttpRunnerManager\HttpRunnerManager\activator.py", line 31, in process
    result = fun(request)
  File "D:/HttpRunnerManager\ApiManager\views.py", line 400, in env_set
    EnvInfo.objects.delete_env(env_lists.get('id'))
  File "D:/HttpRunnerManager\ApiManager\managers.py", line 156, in delete_env
    self.get(id=int(index)).delete()
  File "E:\Python35\lib\site-packages\django\db\models\manager.py", line 82, in manager_method
    return getattr(self.get_queryset(), name)(*args, **kwargs)
  File "E:\Python35\lib\site-packages\django\db\models\query.py", line 403, in get
    self.model._meta.object_name
ApiManager.models.DoesNotExist: EnvInfo matching query does not exist.
2018-04-26 15:08:31,678 [django.request:118] [exception:handle_uncaught_exception] [ERROR]- Internal Server Error: /api/env_set/
Traceback (most recent call last):
  File "E:\Python35\lib\site-packages\django\core\handlers\exception.py", line 35, in inner
    response = get_response(request)
  File "E:\Python35\lib\site-packages\django\utils\deprecation.py", line 97, in __call__
    response = self.process_response(request, response)
  File "E:\Python35\lib\site-packages\django\middleware\clickjacking.py", line 26, in process_response
    if response.get('X-Frame-Options') is not None:
AttributeError: 'str' object has no attribute 'get'
2018-04-26 15:08:59,488 [django.request:118] [exception:handle_uncaught_exception] [ERROR]- Internal Server Error: /api/env_set/
Traceback (most recent call last):
  File "E:\Python35\lib\site-packages\django\core\handlers\exception.py", line 35, in inner
    response = get_response(request)
  File "E:\Python35\lib\site-packages\django\utils\deprecation.py", line 97, in __call__
    response = self.process_response(request, response)
  File "E:\Python35\lib\site-packages\django\middleware\clickjacking.py", line 26, in process_response
    if response.get('X-Frame-Options') is not None:
AttributeError: 'str' object has no attribute 'get'
2018-04-26 15:16:27,255 [django.request:118] [exception:handle_uncaught_exception] [ERROR]- Internal Server Error: /api/test_list/1/
Traceback (most recent call last):
  File "E:\Python35\lib\site-packages\django\core\handlers\exception.py", line 35, in inner
    response = get_response(request)
  File "E:\Python35\lib\site-packages\django\core\handlers\base.py", line 128, in _get_response
    response = self.process_exception_by_middleware(e, request)
  File "E:\Python35\lib\site-packages\django\core\handlers\base.py", line 126, in _get_response
    response = wrapped_callback(request, *callback_args, **callback_kwargs)
  File "D:\HttpRunnerManager\HttpRunnerManager\activator.py", line 29, in process
    result = fun(request, index)
  File "D:\HttpRunnerManager\ApiManager\views.py", line 299, in test_list
    TestCaseInfo, filter_query, '/api/test_list/', id)
  File "D:\HttpRunnerManager\ApiManager\utils\pagination.py", line 140, in get_pager_info
    return page_list, info, sum
UnboundLocalError: local variable 'info' referenced before assignment
2018-05-24 13:39:29,066 [HttpRunnerManager:36] [views:login] [INFO]- yinquanwang 登录成功
2018-05-24 13:39:41,916 [HttpRunnerManager:152] [operation:add_case_data] [INFO]- test_deposit用例更新成功
2018-05-24 13:46:34,437 [HttpRunnerManager:152] [operation:add_case_data] [INFO]- test_deposit用例更新成功
2018-05-24 13:58:26,354 [django.request:118] [exception:handle_uncaught_exception] [ERROR]- Internal Server Error: /api/upload_file/
Traceback (most recent call last):
  File "E:\Python35\lib\site-packages\django\core\handlers\exception.py", line 35, in inner
    response = get_response(request)
  File "E:\Python35\lib\site-packages\django\core\handlers\base.py", line 128, in _get_response
    response = self.process_exception_by_middleware(e, request)
  File "E:\Python35\lib\site-packages\django\core\handlers\base.py", line 126, in _get_response
    response = wrapped_callback(request, *callback_args, **callback_kwargs)
  File "D:/HttpRunnerManager\HttpRunnerManager\activator.py", line 17, in process
    result = fun(request, index) if index else fun(request)
  File "D:/HttpRunnerManager\ApiManager\views.py", line 713, in upload_file
    upload_file_logic(file_list, project_name, module_name, account)
  File "D:/HttpRunnerManager\ApiManager\utils\common.py", line 492, in upload_file_logic
    add_case_data(type=True, **test_case)
  File "D:/HttpRunnerManager\ApiManager\utils\operation.py", line 137, in add_case_data
    belong_module = ModuleInfo.objects.get_module_name(module, type=False)
  File "D:/HttpRunnerManager\ApiManager\managers.py", line 86, in get_module_name
    return self.get(id=module_name)
  File "E:\Python35\lib\site-packages\django\db\models\manager.py", line 82, in manager_method
    return getattr(self.get_queryset(), name)(*args, **kwargs)
  File "E:\Python35\lib\site-packages\django\db\models\query.py", line 394, in get
    clone = self.filter(*args, **kwargs)
  File "E:\Python35\lib\site-packages\django\db\models\query.py", line 836, in filter
    return self._filter_or_exclude(False, *args, **kwargs)
  File "E:\Python35\lib\site-packages\django\db\models\query.py", line 854, in _filter_or_exclude
    clone.query.add_q(Q(*args, **kwargs))
  File "E:\Python35\lib\site-packages\django\db\models\sql\query.py", line 1253, in add_q
    clause, _ = self._add_q(q_object, self.used_aliases)
  File "E:\Python35\lib\site-packages\django\db\models\sql\query.py", line 1277, in _add_q
    split_subq=split_subq,
  File "E:\Python35\lib\site-packages\django\db\models\sql\query.py", line 1215, in build_filter
    condition = self.build_lookup(lookups, col, value)
  File "E:\Python35\lib\site-packages\django\db\models\sql\query.py", line 1085, in build_lookup
    lookup = lookup_class(lhs, rhs)
  File "E:\Python35\lib\site-packages\django\db\models\lookups.py", line 18, in __init__
    self.rhs = self.get_prep_lookup()
  File "E:\Python35\lib\site-packages\django\db\models\lookups.py", line 68, in get_prep_lookup
    return self.lhs.output_field.get_prep_value(self.rhs)
  File "E:\Python35\lib\site-packages\django\db\models\fields\__init__.py", line 947, in get_prep_value
    return int(value)
ValueError: invalid literal for int() with base 10: 'module 2'
2018-05-24 14:00:27,582 [django.request:118] [exception:handle_uncaught_exception] [ERROR]- Internal Server Error: /api/upload_file/
Traceback (most recent call last):
  File "E:\Python35\lib\site-packages\django\core\handlers\exception.py", line 35, in inner
    response = get_response(request)
  File "E:\Python35\lib\site-packages\django\core\handlers\base.py", line 128, in _get_response
    response = self.process_exception_by_middleware(e, request)
  File "E:\Python35\lib\site-packages\django\core\handlers\base.py", line 126, in _get_response
    response = wrapped_callback(request, *callback_args, **callback_kwargs)
  File "D:\HttpRunnerManager\HttpRunnerManager\activator.py", line 17, in process
    result = fun(request, index) if index else fun(request)
  File "D:\HttpRunnerManager\ApiManager\views.py", line 713, in upload_file
    upload_file_logic(file_list, project_name, module_name, account)
  File "D:\HttpRunnerManager\ApiManager\utils\common.py", line 492, in upload_file_logic
    add_case_data(type=True, **test_case)
  File "D:\HttpRunnerManager\ApiManager\utils\operation.py", line 137, in add_case_data
    belong_module = ModuleInfo.objects.get_module_name(module, type=False)
  File "D:\HttpRunnerManager\ApiManager\managers.py", line 86, in get_module_name
    return self.get(id=module_name)
  File "E:\Python35\lib\site-packages\django\db\models\manager.py", line 82, in manager_method
    return getattr(self.get_queryset(), name)(*args, **kwargs)
  File "E:\Python35\lib\site-packages\django\db\models\query.py", line 394, in get
    clone = self.filter(*args, **kwargs)
  File "E:\Python35\lib\site-packages\django\db\models\query.py", line 836, in filter
    return self._filter_or_exclude(False, *args, **kwargs)
  File "E:\Python35\lib\site-packages\django\db\models\query.py", line 854, in _filter_or_exclude
    clone.query.add_q(Q(*args, **kwargs))
  File "E:\Python35\lib\site-packages\django\db\models\sql\query.py", line 1253, in add_q
    clause, _ = self._add_q(q_object, self.used_aliases)
  File "E:\Python35\lib\site-packages\django\db\models\sql\query.py", line 1277, in _add_q
    split_subq=split_subq,
  File "E:\Python35\lib\site-packages\django\db\models\sql\query.py", line 1215, in build_filter
    condition = self.build_lookup(lookups, col, value)
  File "E:\Python35\lib\site-packages\django\db\models\sql\query.py", line 1085, in build_lookup
    lookup = lookup_class(lhs, rhs)
  File "E:\Python35\lib\site-packages\django\db\models\lookups.py", line 18, in __init__
    self.rhs = self.get_prep_lookup()
  File "E:\Python35\lib\site-packages\django\db\models\lookups.py", line 68, in get_prep_lookup
    return self.lhs.output_field.get_prep_value(self.rhs)
  File "E:\Python35\lib\site-packages\django\db\models\fields\__init__.py", line 947, in get_prep_value
    return int(value)
ValueError: invalid literal for int() with base 10: 'module 2'
2018-05-24 14:02:23,292 [HttpRunnerManager:143] [operation:add_case_data] [INFO]- 发发用例添加成功
2018-05-24 14:06:52,162 [HttpRunnerManager:143] [operation:add_case_data] [INFO]- /api/get-token1用例添加成功
2018-05-24 14:06:52,174 [HttpRunnerManager:143] [operation:add_case_data] [INFO]- /api/users/$user_id1用例添加成功
2018-05-24 14:07:11,111 [HttpRunnerManager:143] [operation:add_case_data] [INFO]- /api/get-token1用例添加成功
2018-05-24 14:07:11,124 [HttpRunnerManager:143] [operation:add_case_data] [INFO]- /api/users/$user_id1用例添加成功
2018-05-24 14:07:11,153 [HttpRunnerManager:143] [operation:add_case_data] [INFO]- /api/get-token2用例添加成功
2018-05-24 14:07:11,163 [HttpRunnerManager:143] [operation:add_case_data] [INFO]- /api/users/$user_id2用例添加成功
2018-05-24 14:09:49,770 [HttpRunnerManager:143] [operation:add_case_data] [INFO]- /api/get-token1用例添加成功
2018-05-24 14:09:49,781 [HttpRunnerManager:143] [operation:add_case_data] [INFO]- /api/users/$user_id1用例添加成功
2018-05-24 14:10:26,578 [HttpRunnerManager:143] [operation:add_case_data] [INFO]- /api/get-token1用例添加成功
2018-05-24 14:10:26,590 [HttpRunnerManager:143] [operation:add_case_data] [INFO]- /api/users/$user_id1用例添加成功
2018-05-24 14:10:26,621 [HttpRunnerManager:143] [operation:add_case_data] [INFO]- /api/get-token2用例添加成功
2018-05-24 14:10:26,634 [HttpRunnerManager:143] [operation:add_case_data] [INFO]- /api/users/$user_id2用例添加成功
2018-05-24 14:10:46,216 [HttpRunnerManager:152] [operation:add_case_data] [INFO]- /api/users/$user_id2用例更新成功
2018-05-25 10:15:53,855 [HttpRunnerManager:41] [views:login] [INFO]- yinquanwang 登录成功
2018-05-25 10:16:21,467 [django.request:118] [exception:handle_uncaught_exception] [ERROR]- Internal Server Error: /api/upload_file/
Traceback (most recent call last):
  File "E:\Python35\lib\site-packages\django\core\handlers\exception.py", line 35, in inner
    response = get_response(request)
  File "E:\Python35\lib\site-packages\django\core\handlers\base.py", line 128, in _get_response
    response = self.process_exception_by_middleware(e, request)
  File "E:\Python35\lib\site-packages\django\core\handlers\base.py", line 126, in _get_response
    response = wrapped_callback(request, *callback_args, **callback_kwargs)
  File "D:\HttpRunnerManager\HttpRunnerManager\activator.py", line 17, in process
    result = fun(request, index) if index else fun(request)
  File "D:\HttpRunnerManager\ApiManager\views.py", line 713, in upload_file
    upload_file_logic(file_list, project_name, module_name, account)
  File "D:\HttpRunnerManager\ApiManager\utils\common.py", line 509, in upload_file_logic
    add_config_data(type=True, **test_case)
  File "D:\HttpRunnerManager\ApiManager\utils\operation.py", line 175, in add_config_data
    belong_module = ModuleInfo.objects.get_module_name(module, type=False)
  File "D:\HttpRunnerManager\ApiManager\managers.py", line 87, in get_module_name
    return self.get(id=module_name)
  File "E:\Python35\lib\site-packages\django\db\models\manager.py", line 82, in manager_method
    return getattr(self.get_queryset(), name)(*args, **kwargs)
  File "E:\Python35\lib\site-packages\django\db\models\query.py", line 403, in get
    self.model._meta.object_name
ApiManager.models.DoesNotExist: ModuleInfo matching query does not exist.
2018-05-25 10:22:41,596 [HttpRunnerManager:181] [operation:add_config_data] [INFO]- test config 1配置添加成功
2018-05-25 10:22:45,196 [HttpRunnerManager:190] [operation:add_config_data] [INFO]- test config 1配置更新成功
2018-05-25 10:22:50,071 [HttpRunnerManager:190] [operation:add_config_data] [INFO]- test config 1配置更新成功
2018-05-25 10:23:05,658 [HttpRunnerManager:190] [operation:add_config_data] [INFO]- test config 1配置更新成功
2018-05-25 10:23:19,089 [HttpRunnerManager:181] [operation:add_config_data] [INFO]- 日志配置添加成功
2018-05-25 10:23:19,100 [HttpRunnerManager:143] [operation:add_case_data] [INFO]- api/v1/token正常登录获取token/$devicePlatform用例添加成功
2018-05-25 10:23:19,118 [HttpRunnerManager:143] [operation:add_case_data] [INFO]- /api/v1/users/interest-list iOS/Android工作台应用列表用例添加成功
2018-05-25 10:23:19,129 [HttpRunnerManager:143] [operation:add_case_data] [INFO]- /api/v1/daily/userId/unreadNumber 工作台日志未读数用例添加成功
2018-05-25 10:23:19,141 [HttpRunnerManager:143] [operation:add_case_data] [INFO]- /api/v1/daily/template/type 模板列表用例添加成功
2018-05-25 10:23:19,148 [HttpRunnerManager:143] [operation:add_case_data] [INFO]- api/v1/daily/findDaily发日志前查询用例添加成功
2018-05-25 10:23:19,157 [HttpRunnerManager:143] [operation:add_case_data] [INFO]- /api/v1/daily/saveDaily 编辑提交日志用例添加成功
2018-05-25 10:23:19,163 [HttpRunnerManager:143] [operation:add_case_data] [INFO]- /api/v1/daily/findDaily 日志详情用例添加成功
2018-05-25 10:23:19,173 [HttpRunnerManager:143] [operation:add_case_data] [INFO]- /api/v1/daily/saveDaily 修改日志用例添加成功
2018-05-25 10:23:19,181 [HttpRunnerManager:143] [operation:add_case_data] [INFO]- /api/v1//daily/findDailyUnreadList new_已读未读用例添加成功
2018-05-25 10:23:19,191 [HttpRunnerManager:143] [operation:add_case_data] [INFO]- /api/v1/dailyComment/addComments 添加评论用例添加成功
2018-05-25 10:23:19,201 [HttpRunnerManager:143] [operation:add_case_data] [INFO]- /api/v1/dailyComment/addComments 回复评论用例添加成功
2018-05-25 10:23:19,210 [HttpRunnerManager:143] [operation:add_case_data] [INFO]- /api/v1/dailyComment/deleteComments/删除评论用例添加成功
2018-05-25 10:23:19,217 [HttpRunnerManager:155] [operation:add_case_data] [ERROR]- 用例信息：{'test': {'validate': [{'check': 'status_code', 'expected': 200, 'comparator': 'eq'}, {'check': 'headers.Content-Type', 'expected': 'application/json; charset=UTF-8', 'comparator': 'eq'}, {'check': 'content.status', 'expected': 0, 'comparator': 'eq'}, {'check': 'content.message', 'expected': 'Everything is ok.', 'comparator': 'eq'}], 'variables': [{'version': 0}, {'templateId': 0}, {'checkType': 0}, {'page': 1}, {'size': 20}], 'name': '/api/v1/daily/list new_批阅列表查看我发出的/我收到的、全部日志/日报/周报/月报/工作简报', 'parameters': [{'templateId': [0, 1, 2, 3, 4]}, {'checkType': [0, 1]}], 'extract': [{'result': 'content.result.dailies'}], 'request': {'headers': {}, 'params': {'access_token': '$token'}, 'url': '/api/v1/daily/list', 'json': {'checkType': '$checkType', 'version': '$version', 'lastPublishTime': 0, 'userId': '$userId', 'domainId': '$domainId', 'size': '$size', 'orgCode': '$orgCode', 'page': '$page', 'templateId': '$templateId'}, 'method': 'POST'}}}过长！！
2018-05-25 10:23:19,224 [HttpRunnerManager:155] [operation:add_case_data] [ERROR]- 用例信息：{'test': {'request': {'headers': {}, 'params': {'access_token': '$token'}, 'url': '/api/v1/daily/list', 'json': {'checkType': '$checkType', 'version': '$version', 'lastPublishTime': '$lastPublishTime', 'userId': '$userId', 'domainId': '$domainId', 'size': '$size', 'orgCode': '$orgCode', 'page': '$page', 'templateId': '$templateId'}, 'method': 'POST'}, 'variables': [{'lastPublishTime': '${getLastPublishTime($result)}'}, {'version': 0}, {'templateId': 0}, {'checkType': 0}, {'page': 2}, {'size': 20}], 'name': '/api/v1/daily/list new_批阅列表 上拉加载批阅列表查看我发出的/我收到的、全部日志/日报/周报/月报/工作简报', 'parameters': [{'templateId': [0, 1, 2, 3, 4]}, {'checkType': [0, 1]}], 'validate': [{'check': 'status_code', 'expected': 200, 'comparator': 'eq'}, {'check': 'headers.Content-Type', 'expected': 'application/json; charset=UTF-8', 'comparator': 'eq'}, {'check': 'content.status', 'expected': 0, 'comparator': 'eq'}, {'check': 'content.message', 'expected': 'Everything is ok.', 'comparator': 'eq'}]}}过长！！
2018-05-25 10:23:19,230 [HttpRunnerManager:143] [operation:add_case_data] [INFO]- /api/v1/daily/deleteDaily/ 删除日志用例添加成功
2018-05-25 17:02:24,152 [django.request:93] [base:get_response] [WARNING]- Not Found: /lotto/
2018-05-25 17:03:38,801 [django.request:93] [base:get_response] [WARNING]- Not Found: /lotto/
2018-05-25 17:05:21,631 [django.request:93] [base:get_response] [WARNING]- Not Found: /lotto/
2018-05-25 17:06:18,380 [django.request:93] [base:get_response] [WARNING]- Not Found: /
2018-05-25 17:06:24,022 [django.request:93] [base:get_response] [WARNING]- Not Found: /lotto/
2018-05-31 17:36:38,894 [django.request:118] [exception:handle_uncaught_exception] [ERROR]- Internal Server Error: /api/test_login_valid
Traceback (most recent call last):
  File "E:\Python35\lib\site-packages\django\core\handlers\exception.py", line 35, in inner
    response = get_response(request)
  File "E:\Python35\lib\site-packages\django\utils\deprecation.py", line 93, in __call__
    response = self.process_request(request)
  File "E:\Python35\lib\site-packages\django\middleware\common.py", line 61, in process_request
    path = self.get_full_path_with_slash(request)
  File "E:\Python35\lib\site-packages\django\middleware\common.py", line 99, in get_full_path_with_slash
    'url': request.get_host() + new_path,
RuntimeError: You called this URL via POST, but the URL doesn't end in a slash and you have APPEND_SLASH set. Django can't redirect to the slash URL while maintaining POST data. Change your form to point to 127.0.0.1:8000/api/test_login_valid/ (note the trailing slash), or set APPEND_SLASH=False in your Django settings.
2018-05-31 17:45:21,559 [django.request:118] [exception:handle_uncaught_exception] [ERROR]- Internal Server Error: /api/test_login_json/
Traceback (most recent call last):
  File "E:\Python35\lib\site-packages\django\core\handlers\exception.py", line 35, in inner
    response = get_response(request)
  File "E:\Python35\lib\site-packages\django\core\handlers\base.py", line 128, in _get_response
    response = self.process_exception_by_middleware(e, request)
  File "E:\Python35\lib\site-packages\django\core\handlers\base.py", line 126, in _get_response
    response = wrapped_callback(request, *callback_args, **callback_kwargs)
  File "D:\HttpRunnerManager\HttpRunnerManager\activator.py", line 17, in process
    result = fun(request, index) if index else fun(request)
  File "D:\HttpRunnerManager\ApiManager\views.py", line 749, in test_login_json
    info = json.loads(request.body.decode("utf-8"))
  File "E:\Python35\lib\json\__init__.py", line 319, in loads
    return _default_decoder.decode(s)
  File "E:\Python35\lib\json\decoder.py", line 339, in decode
    obj, end = self.raw_decode(s, idx=_w(s, 0).end())
  File "E:\Python35\lib\json\decoder.py", line 357, in raw_decode
    raise JSONDecodeError("Expecting value", s, err.value) from None
json.decoder.JSONDecodeError: Expecting value: line 1 column 1 (char 0)
2018-05-31 17:46:16,756 [django.request:118] [exception:handle_uncaught_exception] [ERROR]- Internal Server Error: /api/test_login_json/
Traceback (most recent call last):
  File "E:\Python35\lib\site-packages\django\core\handlers\exception.py", line 35, in inner
    response = get_response(request)
  File "E:\Python35\lib\site-packages\django\core\handlers\base.py", line 128, in _get_response
    response = self.process_exception_by_middleware(e, request)
  File "E:\Python35\lib\site-packages\django\core\handlers\base.py", line 126, in _get_response
    response = wrapped_callback(request, *callback_args, **callback_kwargs)
  File "D:\HttpRunnerManager\HttpRunnerManager\activator.py", line 17, in process
    result = fun(request, index) if index else fun(request)
  File "D:\HttpRunnerManager\ApiManager\views.py", line 749, in test_login_json
    info = json.loads(request.body)
  File "E:\Python35\lib\json\__init__.py", line 312, in loads
    s.__class__.__name__))
TypeError: the JSON object must be str, not 'bytes'
2018-05-31 17:46:50,053 [django.request:118] [exception:handle_uncaught_exception] [ERROR]- Internal Server Error: /api/test_login_json/
Traceback (most recent call last):
  File "E:\Python35\lib\site-packages\django\core\handlers\exception.py", line 35, in inner
    response = get_response(request)
  File "E:\Python35\lib\site-packages\django\core\handlers\base.py", line 128, in _get_response
    response = self.process_exception_by_middleware(e, request)
  File "E:\Python35\lib\site-packages\django\core\handlers\base.py", line 126, in _get_response
    response = wrapped_callback(request, *callback_args, **callback_kwargs)
  File "D:/HttpRunnerManager\HttpRunnerManager\activator.py", line 17, in process
    result = fun(request, index) if index else fun(request)
  File "D:/HttpRunnerManager\ApiManager\views.py", line 749, in test_login_json
    info = json.loads(request.body.decode("utf-8"))
  File "E:\Python35\lib\json\__init__.py", line 319, in loads
    return _default_decoder.decode(s)
  File "E:\Python35\lib\json\decoder.py", line 339, in decode
    obj, end = self.raw_decode(s, idx=_w(s, 0).end())
  File "E:\Python35\lib\json\decoder.py", line 357, in raw_decode
    raise JSONDecodeError("Expecting value", s, err.value) from None
json.decoder.JSONDecodeError: Expecting value: line 1 column 1 (char 0)
2018-05-31 17:48:28,764 [django.request:118] [exception:handle_uncaught_exception] [ERROR]- Internal Server Error: /api/test_login_json/
Traceback (most recent call last):
  File "E:\Python35\lib\site-packages\django\core\handlers\exception.py", line 35, in inner
    response = get_response(request)
  File "E:\Python35\lib\site-packages\django\core\handlers\base.py", line 128, in _get_response
    response = self.process_exception_by_middleware(e, request)
  File "E:\Python35\lib\site-packages\django\core\handlers\base.py", line 126, in _get_response
    response = wrapped_callback(request, *callback_args, **callback_kwargs)
  File "D:/HttpRunnerManager\HttpRunnerManager\activator.py", line 17, in process
    result = fun(request, index) if index else fun(request)
  File "D:/HttpRunnerManager\ApiManager\views.py", line 750, in test_login_json
    info = json.loads(request.body)
  File "E:\Python35\lib\json\__init__.py", line 312, in loads
    s.__class__.__name__))
TypeError: the JSON object must be str, not 'bytes'
2018-05-31 17:50:01,770 [django.request:118] [exception:handle_uncaught_exception] [ERROR]- Internal Server Error: /api/test_login_json/
Traceback (most recent call last):
  File "E:\Python35\lib\site-packages\django\core\handlers\exception.py", line 35, in inner
    response = get_response(request)
  File "E:\Python35\lib\site-packages\django\core\handlers\base.py", line 128, in _get_response
    response = self.process_exception_by_middleware(e, request)
  File "E:\Python35\lib\site-packages\django\core\handlers\base.py", line 126, in _get_response
    response = wrapped_callback(request, *callback_args, **callback_kwargs)
  File "D:/HttpRunnerManager\HttpRunnerManager\activator.py", line 17, in process
    result = fun(request, index) if index else fun(request)
  File "D:/HttpRunnerManager\ApiManager\views.py", line 750, in test_login_json
    info = json.loads(request.body)
  File "E:\Python35\lib\json\__init__.py", line 312, in loads
    s.__class__.__name__))
TypeError: the JSON object must be str, not 'bytes'
2018-06-01 09:08:04,905 [django.request:93] [base:get_response] [WARNING]- Not Found: /
2018-06-01 09:08:19,992 [HttpRunnerManager:40] [views:login] [INFO]- yinquanwang 登录成功
2018-06-01 09:22:05,239 [HttpRunnerManager:152] [operation:add_case_data] [INFO]- test_login_2用例更新成功
2018-06-01 09:22:51,924 [HttpRunnerManager:152] [operation:add_case_data] [INFO]- test_login_2用例更新成功
2018-06-01 10:22:23,752 [django.request:93] [base:get_response] [WARNING]- Not Found: /
2018-06-01 10:22:40,307 [HttpRunnerManager:40] [views:login] [INFO]- yinquanwang 登录成功
2018-06-01 10:23:00,814 [HttpRunnerManager:55] [operation:add_project_data] [INFO]- 项目添加成功：{'project_name': 'test project1', 'simple_desc': '', 'dev_user': 'fda', 'publish_app': 'fda', 'other_desc': '', 'test_user': 'fda', 'responsible_name': '22'}
2018-06-01 10:23:15,445 [HttpRunnerManager:103] [operation:add_module_data] [INFO]- 模块添加成功：{'belong_project': <ProjectInfo: ProjectInfo object (29)>, 'test_user': 'fda', 'simple_desc': '', 'module_name': 'fdafad', 'other_desc': ''}
2018-06-01 10:23:27,761 [HttpRunnerManager:152] [operation:add_case_data] [INFO]- test_login_2用例更新成功: {'test': {'variables': [{'username': 'lcc'}, {'password': 'lcc'}], 'extract': [{'code': 'content.code'}, {'status': 'content.status'}], 'validate': [{'comparator': 'equals', 'expected': 'success', 'check': '$code'}, {'comparator': 'equals', 'expected': True, 'check': '$status'}], 'name': 'test_login_2', 'request': {'url': 'http://127.0.0.1:8000/api/test_login_valid/', 'method': 'POST', 'data': {'username': '$username', 'password': '$password'}}}}
2018-06-01 10:24:59,885 [django.request:118] [exception:handle_uncaught_exception] [ERROR]- Internal Server Error: /api/edit_config/
Traceback (most recent call last):
  File "E:\Python35\lib\site-packages\django\core\handlers\exception.py", line 35, in inner
    response = get_response(request)
  File "E:\Python35\lib\site-packages\django\core\handlers\base.py", line 128, in _get_response
    response = self.process_exception_by_middleware(e, request)
  File "E:\Python35\lib\site-packages\django\core\handlers\base.py", line 126, in _get_response
    response = wrapped_callback(request, *callback_args, **callback_kwargs)
  File "D:\HttpRunnerManager\HttpRunnerManager\activator.py", line 17, in process
    result = fun(request, index) if index else fun(request)
  File "D:\HttpRunnerManager\ApiManager\views.py", line 491, in edit_config
    msg = config_info_logic(type=False, **testconfig_lists)
  File "D:\HttpRunnerManager\ApiManager\utils\common.py", line 389, in config_info_logic
    return add_config_data(type, **kwargs)
  File "D:\HttpRunnerManager\ApiManager\utils\operation.py", line 190, in add_config_data
    logger.info('{name}配置更新成功: {kwargs}}'.format(name=name, kwargs = kwargs))
ValueError: Single '}' encountered in format string
2018-06-01 10:25:21,455 [django.request:118] [exception:handle_uncaught_exception] [ERROR]- Internal Server Error: /api/edit_config/
Traceback (most recent call last):
  File "E:\Python35\lib\site-packages\django\core\handlers\exception.py", line 35, in inner
    response = get_response(request)
  File "E:\Python35\lib\site-packages\django\core\handlers\base.py", line 128, in _get_response
    response = self.process_exception_by_middleware(e, request)
  File "E:\Python35\lib\site-packages\django\core\handlers\base.py", line 126, in _get_response
    response = wrapped_callback(request, *callback_args, **callback_kwargs)
  File "D:\HttpRunnerManager\HttpRunnerManager\activator.py", line 17, in process
    result = fun(request, index) if index else fun(request)
  File "D:\HttpRunnerManager\ApiManager\views.py", line 491, in edit_config
    msg = config_info_logic(type=False, **testconfig_lists)
  File "D:\HttpRunnerManager\ApiManager\utils\common.py", line 389, in config_info_logic
    return add_config_data(type, **kwargs)
  File "D:\HttpRunnerManager\ApiManager\utils\operation.py", line 190, in add_config_data
    logger.info('{name}配置更新成功: {kwargs}}'.format(name=name, kwargs = kwargs))
ValueError: Single '}' encountered in format string
2018-06-01 10:25:51,773 [django.request:118] [exception:handle_uncaught_exception] [ERROR]- Internal Server Error: /api/edit_config/
Traceback (most recent call last):
  File "E:\Python35\lib\site-packages\django\core\handlers\exception.py", line 35, in inner
    response = get_response(request)
  File "E:\Python35\lib\site-packages\django\core\handlers\base.py", line 128, in _get_response
    response = self.process_exception_by_middleware(e, request)
  File "E:\Python35\lib\site-packages\django\core\handlers\base.py", line 126, in _get_response
    response = wrapped_callback(request, *callback_args, **callback_kwargs)
  File "D:\HttpRunnerManager\HttpRunnerManager\activator.py", line 17, in process
    result = fun(request, index) if index else fun(request)
  File "D:\HttpRunnerManager\ApiManager\views.py", line 491, in edit_config
    msg = config_info_logic(type=False, **testconfig_lists)
  File "D:\HttpRunnerManager\ApiManager\utils\common.py", line 389, in config_info_logic
    return add_config_data(type, **kwargs)
  File "D:\HttpRunnerManager\ApiManager\utils\operation.py", line 190, in add_config_data
    logger.info('{name}配置更新成功: {kwargs}}'.format(name=name, kwargs=kwargs))
ValueError: Single '}' encountered in format string
2018-06-01 10:26:08,471 [HttpRunnerManager:190] [operation:add_config_data] [INFO]- config 1配置更新成功: {'config': {'teardown_hooks': [], 'request': {}, 'setup_hooks': ['${sleep_N_secs(1)}'], 'name': 'config 1'}}
2018-06-01 10:26:18,400 [HttpRunnerManager:190] [operation:add_config_data] [INFO]- config 1配置更新成功: {'config': {'teardown_hooks': [], 'request': {}, 'setup_hooks': ['${sleep_N_secs(1)}'], 'name': 'config 1'}}
2018-06-01 11:53:28,567 [django.request:93] [base:get_response] [WARNING]- Not Found: /
2018-06-01 11:53:40,275 [HttpRunnerManager:40] [views:login] [INFO]- yinquanwang 登录成功
2018-06-01 12:01:57,598 [django.request:118] [exception:handle_uncaught_exception] [ERROR]- Internal Server Error: /api/test_list/4/
Traceback (most recent call last):
  File "E:\Python35\lib\site-packages\django\template\smartif.py", line 175, in translate_token
    op = OPERATORS[token]
KeyError: '|'

During handling of the above exception, another exception occurred:

Traceback (most recent call last):
  File "E:\Python35\lib\site-packages\django\core\handlers\exception.py", line 35, in inner
    response = get_response(request)
  File "E:\Python35\lib\site-packages\django\core\handlers\base.py", line 128, in _get_response
    response = self.process_exception_by_middleware(e, request)
  File "E:\Python35\lib\site-packages\django\core\handlers\base.py", line 126, in _get_response
    response = wrapped_callback(request, *callback_args, **callback_kwargs)
  File "D:\HttpRunnerManager\HttpRunnerManager\activator.py", line 17, in process
    result = fun(request, index) if index else fun(request)
  File "D:\HttpRunnerManager\ApiManager\views.py", line 405, in test_list
    return render_to_response('test_list.html', manage_info)
  File "E:\Python35\lib\site-packages\django\shortcuts.py", line 27, in render_to_response
    content = loader.render_to_string(template_name, context, using=using)
  File "E:\Python35\lib\site-packages\django\template\loader.py", line 61, in render_to_string
    template = get_template(template_name, using=using)
  File "E:\Python35\lib\site-packages\django\template\loader.py", line 15, in get_template
    return engine.get_template(template_name)
  File "E:\Python35\lib\site-packages\django\template\backends\django.py", line 34, in get_template
    return Template(self.engine.get_template(template_name), self)
  File "E:\Python35\lib\site-packages\django\template\engine.py", line 144, in get_template
    template, origin = self.find_template(template_name)
  File "E:\Python35\lib\site-packages\django\template\engine.py", line 126, in find_template
    template = loader.get_template(name, skip=skip)
  File "E:\Python35\lib\site-packages\django\template\loaders\base.py", line 30, in get_template
    contents, origin, origin.template_name, self.engine,
  File "E:\Python35\lib\site-packages\django\template\base.py", line 160, in __init__
    self.nodelist = self.compile_nodelist()
  File "E:\Python35\lib\site-packages\django\template\base.py", line 198, in compile_nodelist
    return parser.parse()
  File "E:\Python35\lib\site-packages\django\template\base.py", line 483, in parse
    raise self.error(token, e)
  File "E:\Python35\lib\site-packages\django\template\base.py", line 481, in parse
    compiled_result = compile_func(self, token)
  File "E:\Python35\lib\site-packages\django\template\loader_tags.py", line 290, in do_extends
    nodelist = parser.parse()
  File "E:\Python35\lib\site-packages\django\template\base.py", line 483, in parse
    raise self.error(token, e)
  File "E:\Python35\lib\site-packages\django\template\base.py", line 481, in parse
    compiled_result = compile_func(self, token)
  File "E:\Python35\lib\site-packages\django\template\loader_tags.py", line 233, in do_block
    nodelist = parser.parse(('endblock',))
  File "E:\Python35\lib\site-packages\django\template\base.py", line 483, in parse
    raise self.error(token, e)
  File "E:\Python35\lib\site-packages\django\template\base.py", line 481, in parse
    compiled_result = compile_func(self, token)
  File "E:\Python35\lib\site-packages\django\template\defaulttags.py", line 815, in do_for
    nodelist_loop = parser.parse(('empty', 'endfor',))
  File "E:\Python35\lib\site-packages\django\template\base.py", line 483, in parse
    raise self.error(token, e)
  File "E:\Python35\lib\site-packages\django\template\base.py", line 481, in parse
    compiled_result = compile_func(self, token)
  File "E:\Python35\lib\site-packages\django\template\defaulttags.py", line 955, in do_if
    condition = TemplateIfParser(parser, bits).parse()
  File "E:\Python35\lib\site-packages\django\template\defaulttags.py", line 888, in __init__
    super().__init__(*args, **kwargs)
  File "E:\Python35\lib\site-packages\django\template\smartif.py", line 166, in __init__
    mapped_tokens.append(self.translate_token(token))
  File "E:\Python35\lib\site-packages\django\template\smartif.py", line 177, in translate_token
    return self.create_var(token)
  File "E:\Python35\lib\site-packages\django\template\defaulttags.py", line 891, in create_var
    return TemplateLiteral(self.template_parser.compile_filter(value), value)
  File "E:\Python35\lib\site-packages\django\template\base.py", line 568, in compile_filter
    return FilterExpression(token, self)
  File "E:\Python35\lib\site-packages\django\template\base.py", line 668, in __init__
    "from '%s'" % (token[upto:], token))
django.template.exceptions.TemplateSyntaxError: Could not parse the remainder: '|' from '|'
2018-06-01 12:03:51,385 [django.request:118] [exception:handle_uncaught_exception] [ERROR]- Internal Server Error: /api/test_list/4/
Traceback (most recent call last):
  File "E:\Python35\lib\site-packages\django\core\handlers\exception.py", line 35, in inner
    response = get_response(request)
  File "E:\Python35\lib\site-packages\django\core\handlers\base.py", line 128, in _get_response
    response = self.process_exception_by_middleware(e, request)
  File "E:\Python35\lib\site-packages\django\core\handlers\base.py", line 126, in _get_response
    response = wrapped_callback(request, *callback_args, **callback_kwargs)
  File "D:\HttpRunnerManager\HttpRunnerManager\activator.py", line 17, in process
    result = fun(request, index) if index else fun(request)
  File "D:\HttpRunnerManager\ApiManager\views.py", line 405, in test_list
    return render_to_response('test_list.html', manage_info)
  File "E:\Python35\lib\site-packages\django\shortcuts.py", line 27, in render_to_response
    content = loader.render_to_string(template_name, context, using=using)
  File "E:\Python35\lib\site-packages\django\template\loader.py", line 61, in render_to_string
    template = get_template(template_name, using=using)
  File "E:\Python35\lib\site-packages\django\template\loader.py", line 15, in get_template
    return engine.get_template(template_name)
  File "E:\Python35\lib\site-packages\django\template\backends\django.py", line 34, in get_template
    return Template(self.engine.get_template(template_name), self)
  File "E:\Python35\lib\site-packages\django\template\engine.py", line 144, in get_template
    template, origin = self.find_template(template_name)
  File "E:\Python35\lib\site-packages\django\template\engine.py", line 126, in find_template
    template = loader.get_template(name, skip=skip)
  File "E:\Python35\lib\site-packages\django\template\loaders\base.py", line 30, in get_template
    contents, origin, origin.template_name, self.engine,
  File "E:\Python35\lib\site-packages\django\template\base.py", line 160, in __init__
    self.nodelist = self.compile_nodelist()
  File "E:\Python35\lib\site-packages\django\template\base.py", line 198, in compile_nodelist
    return parser.parse()
  File "E:\Python35\lib\site-packages\django\template\base.py", line 483, in parse
    raise self.error(token, e)
  File "E:\Python35\lib\site-packages\django\template\base.py", line 481, in parse
    compiled_result = compile_func(self, token)
  File "E:\Python35\lib\site-packages\django\template\loader_tags.py", line 290, in do_extends
    nodelist = parser.parse()
  File "E:\Python35\lib\site-packages\django\template\base.py", line 483, in parse
    raise self.error(token, e)
  File "E:\Python35\lib\site-packages\django\template\base.py", line 481, in parse
    compiled_result = compile_func(self, token)
  File "E:\Python35\lib\site-packages\django\template\loader_tags.py", line 233, in do_block
    nodelist = parser.parse(('endblock',))
  File "E:\Python35\lib\site-packages\django\template\base.py", line 483, in parse
    raise self.error(token, e)
  File "E:\Python35\lib\site-packages\django\template\base.py", line 481, in parse
    compiled_result = compile_func(self, token)
  File "E:\Python35\lib\site-packages\django\template\defaulttags.py", line 815, in do_for
    nodelist_loop = parser.parse(('empty', 'endfor',))
  File "E:\Python35\lib\site-packages\django\template\base.py", line 483, in parse
    raise self.error(token, e)
  File "E:\Python35\lib\site-packages\django\template\base.py", line 481, in parse
    compiled_result = compile_func(self, token)
  File "E:\Python35\lib\site-packages\django\template\defaulttags.py", line 955, in do_if
    condition = TemplateIfParser(parser, bits).parse()
  File "E:\Python35\lib\site-packages\django\template\smartif.py", line 194, in parse
    self.current_token.display())
django.template.exceptions.TemplateSyntaxError: Unused '3' at end of if expression.
2018-06-01 13:33:34,888 [HttpRunnerManager:40] [views:login] [INFO]- yinquanwang 登录成功
2018-06-01 13:34:09,536 [HttpRunnerManager:152] [operation:add_case_data] [INFO]- test_login_2用例更新成功: {'test': {'extract': [{'code': 'content.code'}, {'status': 'content.status'}], 'variables': [{'username': '${get_value(lcc)}'}, {'password': '${get_value(lcc)}'}], 'name': 'test_login_2', 'validate': [{'comparator': 'equals', 'expected': 'success', 'check': '$code'}, {'comparator': 'equals', 'expected': True, 'check': '$status'}], 'request': {'method': 'POST', 'data': {'password': '$password', 'username': '$username'}, 'url': 'http://127.0.0.1:8000/api/test_login_valid/'}}}
2018-06-01 14:05:30,016 [HttpRunnerManager:40] [views:login] [INFO]- yinquanwang 登录成功
